Workbook

Sheet Hoja1
A1: NET | B1: 0DTE | C1: NEXT_FRIDAY | D1: NEXT_OPEX | E1: GEX-VOL | F1: =+[1]Sheet1!$AD$2 -> 630.49396 | H1: =+B2 -> 251110 | I1: =+H1 -> 251110 | J1: =+C2 -> 251114 | K1: =+J1 -> 251114 | L1: =+D2 -> 251121 | M1: =+L1 -> 251121 | N1: =+A3 -> 672.36 | P1: =+H1 -> 251110 | R1: =+J1 -> 251114 | T1: =+L1 -> 251121 | U1: =+N1 -> 672.36 | W1: =MAX(W4:W38) -> 213626
A2: SPY | B2: =+TEXT(B42,"YYMMDD") -> 251110 | C2: =+TEXT(C42,"YYMMDD") -> 251114 | D2: =+TEXT(D42,"YYMMDD") -> 251121 | F2: /ES:XCME | H2: OPEN_INT | I2: OPEN_INT | J2: OPEN_INT | K2: OPEN_INT | L2: OPEN_INT | M2: OPEN_INT | N2: NET OI | P2: VOLUME | Q2: =+P2 -> VOLUME | R2: VOLUME | S2: VOLUME | T2: VOLUME | U2: VOLUME | W2: NET VOL
A3: =+A40 -> 672.36 | B3: =+H3/I3 -> -0.95509487 | C3: =+J3/K3 -> -0.59722692 | D3: =+L3/M3 -> -0.66167469 | E3: 0 | F3: =RTD("tos.rtd", ,"MARK", F2) -> 6765 | H3: =SUM(H4:H38) -> 82099 | I3: =SUM(I4:I38) -> -85959 | J3: =SUM(J4:J38) -> 75852 | K3: =SUM(K4:K38) -> -127007 | L3: =SUM(L4:L38) -> 211325 | M3: =SUM(M4:M38) -> -319379 | N3: =SUM(N4:N38) -> -163069 | O3: 0 | P3: =SUM(P4:P38) -> 791834 | Q3: =SUM(Q4:Q38) -> -701778 | R3: =SUM(R4:R38) -> 241878 | S3: =SUM(S4:S38) -> -167850 | T3: =SUM(T4:T38) -> 117466 | U3: =SUM(U4:U38) -> -126387 | W3: =SUM(W4:W38) -> 359278
A4: =ROUND(A3/$A$39,0)*$A$39+17*$A$39 -> 689 | B4: =+IF($A$1="ABS",H4-I4,H4+I4) -> 1990 | C4: =+IF($A$1="ABS",J4-K4,J4+K4) -> 409 | D4: =+IF($A$1="ABS",L4-M4,L4+M4) -> 1237 | E4: =SUM(B4:D4) -> 3636 | F4: =+$F$3/$A$3*A4 -> 6932.4246 | H4: =IF(RTD("tos.rtd",,H$2,"."&$A$2&$H$1&"C"&$A4)="N/A",0,RTD("tos.rtd",,H$2,"."&$A$2&$H$1&"C"&$A4)) -> 1997 | I4: =-IF(RTD("tos.rtd",,I$2,"."&$A$2&$H$1&"P"&$A4)="N/A",0,RTD("tos.rtd",,I$2,"."&$A$2&$H$1&"P"&$A4)) -> -7 | J4: =IF(RTD("tos.rtd",,J$2,"."&$A$2&$J$1&"C"&$A4)="N/A",0,RTD("tos.rtd",,J$2,"."&$A$2&$J$1&"C"&$A4)) -> 1589 | K4: =-IF(RTD("tos.rtd",,K$2,"."&$A$2&$J$1&"P"&$A4)="N/A",0,RTD("tos.rtd",,K$2,"."&$A$2&$J$1&"P"&$A4)) -> -1180 | L4: =IF(RTD("tos.rtd",,L$2,"."&$A$2&$L$1&"C"&$A4)="N/A",0,RTD("tos.rtd",,L$2,"."&$A$2&$L$1&"C"&$A4)) -> 2324 | M4: =-IF(RTD("tos.rtd",,M$2,"."&$A$2&$L$1&"P"&$A4)="N/A",0,RTD("tos.rtd",,M$2,"."&$A$2&$L$1&"P"&$A4)) -> -1087 | N4: =SUM(H4:M4) -> 3636 | O4: =+A4 -> 689 | P4: =IF(RTD("tos.rtd",,P$2,"."&$A$2&$H$1&"C"&$A4)="N/A",0,RTD("tos.rtd",,P$2,"."&$A$2&$H$1&"C"&$A4)) -> 593 | Q4: =-IF(RTD("tos.rtd",,Q$2,"."&$A$2&$H$1&"P"&$A4)="N/A",0,RTD("tos.rtd",,Q$2,"."&$A$2&$H$1&"P"&$A4)) -> -44 | R4: =IF(RTD("tos.rtd",,R$2,"."&$A$2&$J$1&"C"&$A4)="N/A",0,RTD("tos.rtd",,R$2,"."&$A$2&$J$1&"C"&$A4)) -> 1371 | S4: =-IF(RTD("tos.rtd",,S$2,"."&$A$2&$J$1&"P"&$A4)="N/A",0,RTD("tos.rtd",,S$2,"."&$A$2&$J$1&"P"&$A4)) -> -89 | T4: =IF(RTD("tos.rtd",,T$2,"."&$A$2&$L$1&"C"&$A4)="N/A",0,RTD("tos.rtd",,T$2,"."&$A$2&$L$1&"C"&$A4)) -> 1140 | U4: =-IF(RTD("tos.rtd",,U$2,"."&$A$2&$L$1&"P"&$A4)="N/A",0,RTD("tos.rtd",,U$2,"."&$A$2&$L$1&"P"&$A4)) -> -73 | V4: =+Hoja2!Y5 -> 3001 | W4: =SUM(P4:V4) -> 5899
A5: =+A4-$A$39 -> 688 | B5: =+IF($A$1="ABS",H5-I5,H5+I5) -> 4243 | C5: =+IF($A$1="ABS",J5-K5,J5+K5) -> 1741 | D5: =+IF($A$1="ABS",L5-M5,L5+M5) -> 3601 | E5: =SUM(B5:D5) -> 9585 | F5: =+$F$3/$A$3*A5 -> 6922.363 | H5: =IF(RTD("tos.rtd",,H$2,"."&$A$2&$H$1&"C"&$A5)="N/A",0,RTD("tos.rtd",,H$2,"."&$A$2&$H$1&"C"&$A5)) -> 4258 | I5: =-IF(RTD("tos.rtd",,I$2,"."&$A$2&$H$1&"P"&$A5)="N/A",0,RTD("tos.rtd",,I$2,"."&$A$2&$H$1&"P"&$A5)) -> -15 | J5: =IF(RTD("tos.rtd",,J$2,"."&$A$2&$J$1&"C"&$A5)="N/A",0,RTD("tos.rtd",,J$2,"."&$A$2&$J$1&"C"&$A5)) -> 3007 | K5: =-IF(RTD("tos.rtd",,K$2,"."&$A$2&$J$1&"P"&$A5)="N/A",0,RTD("tos.rtd",,K$2,"."&$A$2&$J$1&"P"&$A5)) -> -1266 | L5: =IF(RTD("tos.rtd",,L$2,"."&$A$2&$L$1&"C"&$A5)="N/A",0,RTD("tos.rtd",,L$2,"."&$A$2&$L$1&"C"&$A5)) -> 6256 | M5: =-IF(RTD("tos.rtd",,M$2,"."&$A$2&$L$1&"P"&$A5)="N/A",0,RTD("tos.rtd",,M$2,"."&$A$2&$L$1&"P"&$A5)) -> -2655 | N5: =SUM(H5:M5) -> 9585 | O5: =+A5 -> 688 | P5: =IF(RTD("tos.rtd",,P$2,"."&$A$2&$H$1&"C"&$A5)="N/A",0,RTD("tos.rtd",,P$2,"."&$A$2&$H$1&"C"&$A5)) -> 2525 | Q5: =-IF(RTD("tos.rtd",,Q$2,"."&$A$2&$H$1&"P"&$A5)="N/A",0,RTD("tos.rtd",,Q$2,"."&$A$2&$H$1&"P"&$A5)) -> -309 | R5: =IF(RTD("tos.rtd",,R$2,"."&$A$2&$J$1&"C"&$A5)="N/A",0,RTD("tos.rtd",,R$2,"."&$A$2&$J$1&"C"&$A5)) -> 2552 | S5: =-IF(RTD("tos.rtd",,S$2,"."&$A$2&$J$1&"P"&$A5)="N/A",0,RTD("tos.rtd",,S$2,"."&$A$2&$J$1&"P"&$A5)) -> -19 | T5: =IF(RTD("tos.rtd",,T$2,"."&$A$2&$L$1&"C"&$A5)="N/A",0,RTD("tos.rtd",,T$2,"."&$A$2&$L$1&"C"&$A5)) -> 3042 | U5: =-IF(RTD("tos.rtd",,U$2,"."&$A$2&$L$1&"P"&$A5)="N/A",0,RTD("tos.rtd",,U$2,"."&$A$2&$L$1&"P"&$A5)) -> -270 | V5: =+Hoja2!Y6 -> 4683 | W5: =SUM(P5:V5) -> 12204
A6: =+A5-$A$39 -> 687 | B6: =+IF($A$1="ABS",H6-I6,H6+I6) -> 1390 | C6: =+IF($A$1="ABS",J6-K6,J6+K6) -> 4747 | D6: =+IF($A$1="ABS",L6-M6,L6+M6) -> 37 | E6: =SUM(B6:D6) -> 6174 | F6: =+$F$3/$A$3*A6 -> 6912.3014 | H6: =IF(RTD("tos.rtd",,H$2,"."&$A$2&$H$1&"C"&$A6)="N/A",0,RTD("tos.rtd",,H$2,"."&$A$2&$H$1&"C"&$A6)) -> 1391 | I6: =-IF(RTD("tos.rtd",,I$2,"."&$A$2&$H$1&"P"&$A6)="N/A",0,RTD("tos.rtd",,I$2,"."&$A$2&$H$1&"P"&$A6)) -> -1 | J6: =IF(RTD("tos.rtd",,J$2,"."&$A$2&$J$1&"C"&$A6)="N/A",0,RTD("tos.rtd",,J$2,"."&$A$2&$J$1&"C"&$A6)) -> 5771 | K6: =-IF(RTD("tos.rtd",,K$2,"."&$A$2&$J$1&"P"&$A6)="N/A",0,RTD("tos.rtd",,K$2,"."&$A$2&$J$1&"P"&$A6)) -> -1024 | L6: =IF(RTD("tos.rtd",,L$2,"."&$A$2&$L$1&"C"&$A6)="N/A",0,RTD("tos.rtd",,L$2,"."&$A$2&$L$1&"C"&$A6)) -> 1834 | M6: =-IF(RTD("tos.rtd",,M$2,"."&$A$2&$L$1&"P"&$A6)="N/A",0,RTD("tos.rtd",,M$2,"."&$A$2&$L$1&"P"&$A6)) -> -1797 | N6: =SUM(H6:M6) -> 6174 | O6: =+A6 -> 687 | P6: =IF(RTD("tos.rtd",,P$2,"."&$A$2&$H$1&"C"&$A6)="N/A",0,RTD("tos.rtd",,P$2,"."&$A$2&$H$1&"C"&$A6)) -> 1915 | Q6: =-IF(RTD("tos.rtd",,Q$2,"."&$A$2&$H$1&"P"&$A6)="N/A",0,RTD("tos.rtd",,Q$2,"."&$A$2&$H$1&"P"&$A6)) -> -51 | R6: =IF(RTD("tos.rtd",,R$2,"."&$A$2&$J$1&"C"&$A6)="N/A",0,RTD("tos.rtd",,R$2,"."&$A$2&$J$1&"C"&$A6)) -> 3790 | S6: =-IF(RTD("tos.rtd",,S$2,"."&$A$2&$J$1&"P"&$A6)="N/A",0,RTD("tos.rtd",,S$2,"."&$A$2&$J$1&"P"&$A6)) -> -170 | T6: =IF(RTD("tos.rtd",,T$2,"."&$A$2&$L$1&"C"&$A6)="N/A",0,RTD("tos.rtd",,T$2,"."&$A$2&$L$1&"C"&$A6)) -> 1448 | U6: =-IF(RTD("tos.rtd",,U$2,"."&$A$2&$L$1&"P"&$A6)="N/A",0,RTD("tos.rtd",,U$2,"."&$A$2&$L$1&"P"&$A6)) -> -32 | V6: =+Hoja2!Y7 -> 4548 | W6: =SUM(P6:V6) -> 11448
A7: =+A6-$A$39 -> 686 | B7: =+IF($A$1="ABS",H7-I7,H7+I7) -> 4021 | C7: =+IF($A$1="ABS",J7-K7,J7+K7) -> 1282 | D7: =+IF($A$1="ABS",L7-M7,L7+M7) -> 2671 | E7: =SUM(B7:D7) -> 7974 | F7: =+$F$3/$A$3*A7 -> 6902.2399 | H7: =IF(RTD("tos.rtd",,H$2,"."&$A$2&$H$1&"C"&$A7)="N/A",0,RTD("tos.rtd",,H$2,"."&$A$2&$H$1&"C"&$A7)) -> 4066 | I7: =-IF(RTD("tos.rtd",,I$2,"."&$A$2&$H$1&"P"&$A7)="N/A",0,RTD("tos.rtd",,I$2,"."&$A$2&$H$1&"P"&$A7)) -> -45 | J7: =IF(RTD("tos.rtd",,J$2,"."&$A$2&$J$1&"C"&$A7)="N/A",0,RTD("tos.rtd",,J$2,"."&$A$2&$J$1&"C"&$A7)) -> 2277 | K7: =-IF(RTD("tos.rtd",,K$2,"."&$A$2&$J$1&"P"&$A7)="N/A",0,RTD("tos.rtd",,K$2,"."&$A$2&$J$1&"P"&$A7)) -> -995 | L7: =IF(RTD("tos.rtd",,L$2,"."&$A$2&$L$1&"C"&$A7)="N/A",0,RTD("tos.rtd",,L$2,"."&$A$2&$L$1&"C"&$A7)) -> 5024 | M7: =-IF(RTD("tos.rtd",,M$2,"."&$A$2&$L$1&"P"&$A7)="N/A",0,RTD("tos.rtd",,M$2,"."&$A$2&$L$1&"P"&$A7)) -> -2353 | N7: =SUM(H7:M7) -> 7974 | O7: =+A7 -> 686 | P7: =IF(RTD("tos.rtd",,P$2,"."&$A$2&$H$1&"C"&$A7)="N/A",0,RTD("tos.rtd",,P$2,"."&$A$2&$H$1&"C"&$A7)) -> 3715 | Q7: =-IF(RTD("tos.rtd",,Q$2,"."&$A$2&$H$1&"P"&$A7)="N/A",0,RTD("tos.rtd",,Q$2,"."&$A$2&$H$1&"P"&$A7)) -> -759 | R7: =IF(RTD("tos.rtd",,R$2,"."&$A$2&$J$1&"C"&$A7)="N/A",0,RTD("tos.rtd",,R$2,"."&$A$2&$J$1&"C"&$A7)) -> 4475 | S7: =-IF(RTD("tos.rtd",,S$2,"."&$A$2&$J$1&"P"&$A7)="N/A",0,RTD("tos.rtd",,S$2,"."&$A$2&$J$1&"P"&$A7)) -> -239 | T7: =IF(RTD("tos.rtd",,T$2,"."&$A$2&$L$1&"C"&$A7)="N/A",0,RTD("tos.rtd",,T$2,"."&$A$2&$L$1&"C"&$A7)) -> 1800 | U7: =-IF(RTD("tos.rtd",,U$2,"."&$A$2&$L$1&"P"&$A7)="N/A",0,RTD("tos.rtd",,U$2,"."&$A$2&$L$1&"P"&$A7)) -> -84 | V7: =+Hoja2!Y8 -> 9798 | W7: =SUM(P7:V7) -> 18706
A8: =+A7-$A$39 -> 685 | B8: =+IF($A$1="ABS",H8-I8,H8+I8) -> 9403 | C8: =+IF($A$1="ABS",J8-K8,J8+K8) -> 2019 | D8: =+IF($A$1="ABS",L8-M8,L8+M8) -> 10553 | E8: =SUM(B8:D8) -> 21975 | F8: =+$F$3/$A$3*A8 -> 6892.1783 | H8: =IF(RTD("tos.rtd",,H$2,"."&$A$2&$H$1&"C"&$A8)="N/A",0,RTD("tos.rtd",,H$2,"."&$A$2&$H$1&"C"&$A8)) -> 9523 | I8: =-IF(RTD("tos.rtd",,I$2,"."&$A$2&$H$1&"P"&$A8)="N/A",0,RTD("tos.rtd",,I$2,"."&$A$2&$H$1&"P"&$A8)) -> -120 | J8: =IF(RTD("tos.rtd",,J$2,"."&$A$2&$J$1&"C"&$A8)="N/A",0,RTD("tos.rtd",,J$2,"."&$A$2&$J$1&"C"&$A8)) -> 9060 | K8: =-IF(RTD("tos.rtd",,K$2,"."&$A$2&$J$1&"P"&$A8)="N/A",0,RTD("tos.rtd",,K$2,"."&$A$2&$J$1&"P"&$A8)) -> -7041 | L8: =IF(RTD("tos.rtd",,L$2,"."&$A$2&$L$1&"C"&$A8)="N/A",0,RTD("tos.rtd",,L$2,"."&$A$2&$L$1&"C"&$A8)) -> 16785 | M8: =-IF(RTD("tos.rtd",,M$2,"."&$A$2&$L$1&"P"&$A8)="N/A",0,RTD("tos.rtd",,M$2,"."&$A$2&$L$1&"P"&$A8)) -> -6232 | N8: =SUM(H8:M8) -> 21975 | O8: =+A8 -> 685 | P8: =IF(RTD("tos.rtd",,P$2,"."&$A$2&$H$1&"C"&$A8)="N/A",0,RTD("tos.rtd",,P$2,"."&$A$2&$H$1&"C"&$A8)) -> 9694 | Q8: =-IF(RTD("tos.rtd",,Q$2,"."&$A$2&$H$1&"P"&$A8)="N/A",0,RTD("tos.rtd",,Q$2,"."&$A$2&$H$1&"P"&$A8)) -> -640 | R8: =IF(RTD("tos.rtd",,R$2,"."&$A$2&$J$1&"C"&$A8)="N/A",0,RTD("tos.rtd",,R$2,"."&$A$2&$J$1&"C"&$A8)) -> 9166 | S8: =-IF(RTD("tos.rtd",,S$2,"."&$A$2&$J$1&"P"&$A8)="N/A",0,RTD("tos.rtd",,S$2,"."&$A$2&$J$1&"P"&$A8)) -> -383 | T8: =IF(RTD("tos.rtd",,T$2,"."&$A$2&$L$1&"C"&$A8)="N/A",0,RTD("tos.rtd",,T$2,"."&$A$2&$L$1&"C"&$A8)) -> 12720 | U8: =-IF(RTD("tos.rtd",,U$2,"."&$A$2&$L$1&"P"&$A8)="N/A",0,RTD("tos.rtd",,U$2,"."&$A$2&$L$1&"P"&$A8)) -> -489 | V8: =+Hoja2!Y9 -> 25311 | W8: =SUM(P8:V8) -> 55379
A9: =+A8-$A$39 -> 684 | B9: =+IF($A$1="ABS",H9-I9,H9+I9) -> 2805 | C9: =+IF($A$1="ABS",J9-K9,J9+K9) -> 2060 | D9: =+IF($A$1="ABS",L9-M9,L9+M9) -> 1486 | E9: =SUM(B9:D9) -> 6351 | F9: =+$F$3/$A$3*A9 -> 6882.1167 | H9: =IF(RTD("tos.rtd",,H$2,"."&$A$2&$H$1&"C"&$A9)="N/A",0,RTD("tos.rtd",,H$2,"."&$A$2&$H$1&"C"&$A9)) -> 2863 | I9: =-IF(RTD("tos.rtd",,I$2,"."&$A$2&$H$1&"P"&$A9)="N/A",0,RTD("tos.rtd",,I$2,"."&$A$2&$H$1&"P"&$A9)) -> -58 | J9: =IF(RTD("tos.rtd",,J$2,"."&$A$2&$J$1&"C"&$A9)="N/A",0,RTD("tos.rtd",,J$2,"."&$A$2&$J$1&"C"&$A9)) -> 3097 | K9: =-IF(RTD("tos.rtd",,K$2,"."&$A$2&$J$1&"P"&$A9)="N/A",0,RTD("tos.rtd",,K$2,"."&$A$2&$J$1&"P"&$A9)) -> -1037 | L9: =IF(RTD("tos.rtd",,L$2,"."&$A$2&$L$1&"C"&$A9)="N/A",0,RTD("tos.rtd",,L$2,"."&$A$2&$L$1&"C"&$A9)) -> 3826 | M9: =-IF(RTD("tos.rtd",,M$2,"."&$A$2&$L$1&"P"&$A9)="N/A",0,RTD("tos.rtd",,M$2,"."&$A$2&$L$1&"P"&$A9)) -> -2340 | N9: =SUM(H9:M9) -> 6351 | O9: =+A9 -> 684 | P9: =IF(RTD("tos.rtd",,P$2,"."&$A$2&$H$1&"C"&$A9)="N/A",0,RTD("tos.rtd",,P$2,"."&$A$2&$H$1&"C"&$A9)) -> 4102 | Q9: =-IF(RTD("tos.rtd",,Q$2,"."&$A$2&$H$1&"P"&$A9)="N/A",0,RTD("tos.rtd",,Q$2,"."&$A$2&$H$1&"P"&$A9)) -> -27 | R9: =IF(RTD("tos.rtd",,R$2,"."&$A$2&$J$1&"C"&$A9)="N/A",0,RTD("tos.rtd",,R$2,"."&$A$2&$J$1&"C"&$A9)) -> 2394 | S9: =-IF(RTD("tos.rtd",,S$2,"."&$A$2&$J$1&"P"&$A9)="N/A",0,RTD("tos.rtd",,S$2,"."&$A$2&$J$1&"P"&$A9)) -> -501 | T9: =IF(RTD("tos.rtd",,T$2,"."&$A$2&$L$1&"C"&$A9)="N/A",0,RTD("tos.rtd",,T$2,"."&$A$2&$L$1&"C"&$A9)) -> 1539 | U9: =-IF(RTD("tos.rtd",,U$2,"."&$A$2&$L$1&"P"&$A9)="N/A",0,RTD("tos.rtd",,U$2,"."&$A$2&$L$1&"P"&$A9)) -> -60 | V9: =+Hoja2!Y10 -> 8593 | W9: =SUM(P9:V9) -> 16040
A10: =+A9-$A$39 -> 683 | B10: =+IF($A$1="ABS",H10-I10,H10+I10) -> 1812 | C10: =+IF($A$1="ABS",J10-K10,J10+K10) -> 1035 | D10: =+IF($A$1="ABS",L10-M10,L10+M10) -> -305 | E10: =SUM(B10:D10) -> 2542 | F10: =+$F$3/$A$3*A10 -> 6872.0551 | H10: =IF(RTD("tos.rtd",,H$2,"."&$A$2&$H$1&"C"&$A10)="N/A",0,RTD("tos.rtd",,H$2,"."&$A$2&$H$1&"C"&$A10)) -> 2091 | I10: =-IF(RTD("tos.rtd",,I$2,"."&$A$2&$H$1&"P"&$A10)="N/A",0,RTD("tos.rtd",,I$2,"."&$A$2&$H$1&"P"&$A10)) -> -279 | J10: =IF(RTD("tos.rtd",,J$2,"."&$A$2&$J$1&"C"&$A10)="N/A",0,RTD("tos.rtd",,J$2,"."&$A$2&$J$1&"C"&$A10)) -> 1898 | K10: =-IF(RTD("tos.rtd",,K$2,"."&$A$2&$J$1&"P"&$A10)="N/A",0,RTD("tos.rtd",,K$2,"."&$A$2&$J$1&"P"&$A10)) -> -863 | L10: =IF(RTD("tos.rtd",,L$2,"."&$A$2&$L$1&"C"&$A10)="N/A",0,RTD("tos.rtd",,L$2,"."&$A$2&$L$1&"C"&$A10)) -> 4181 | M10: =-IF(RTD("tos.rtd",,M$2,"."&$A$2&$L$1&"P"&$A10)="N/A",0,RTD("tos.rtd",,M$2,"."&$A$2&$L$1&"P"&$A10)) -> -4486 | N10: =SUM(H10:M10) -> 2542 | O10: =+A10 -> 683 | P10: =IF(RTD("tos.rtd",,P$2,"."&$A$2&$H$1&"C"&$A10)="N/A",0,RTD("tos.rtd",,P$2,"."&$A$2&$H$1&"C"&$A10)) -> 5745 | Q10: =-IF(RTD("tos.rtd",,Q$2,"."&$A$2&$H$1&"P"&$A10)="N/A",0,RTD("tos.rtd",,Q$2,"."&$A$2&$H$1&"P"&$A10)) -> -115 | R10: =IF(RTD("tos.rtd",,R$2,"."&$A$2&$J$1&"C"&$A10)="N/A",0,RTD("tos.rtd",,R$2,"."&$A$2&$J$1&"C"&$A10)) -> 2136 | S10: =-IF(RTD("tos.rtd",,S$2,"."&$A$2&$J$1&"P"&$A10)="N/A",0,RTD("tos.rtd",,S$2,"."&$A$2&$J$1&"P"&$A10)) -> -66 | T10: =IF(RTD("tos.rtd",,T$2,"."&$A$2&$L$1&"C"&$A10)="N/A",0,RTD("tos.rtd",,T$2,"."&$A$2&$L$1&"C"&$A10)) -> 1765 | U10: =-IF(RTD("tos.rtd",,U$2,"."&$A$2&$L$1&"P"&$A10)="N/A",0,RTD("tos.rtd",,U$2,"."&$A$2&$L$1&"P"&$A10)) -> -114 | V10: =+Hoja2!Y11 -> 18266 | W10: =SUM(P10:V10) -> 27617
A11: =+A10-$A$39 -> 682 | B11: =+IF($A$1="ABS",H11-I11,H11+I11) -> 6639 | C11: =+IF($A$1="ABS",J11-K11,J11+K11) -> 710 | D11: =+IF($A$1="ABS",L11-M11,L11+M11) -> 426 | E11: =SUM(B11:D11) -> 7775 | F11: =+$F$3/$A$3*A11 -> 6861.9936 | H11: =IF(RTD("tos.rtd",,H$2,"."&$A$2&$H$1&"C"&$A11)="N/A",0,RTD("tos.rtd",,H$2,"."&$A$2&$H$1&"C"&$A11)) -> 7117 | I11: =-IF(RTD("tos.rtd",,I$2,"."&$A$2&$H$1&"P"&$A11)="N/A",0,RTD("tos.rtd",,I$2,"."&$A$2&$H$1&"P"&$A11)) -> -478 | J11: =IF(RTD("tos.rtd",,J$2,"."&$A$2&$J$1&"C"&$A11)="N/A",0,RTD("tos.rtd",,J$2,"."&$A$2&$J$1&"C"&$A11)) -> 2069 | K11: =-IF(RTD("tos.rtd",,K$2,"."&$A$2&$J$1&"P"&$A11)="N/A",0,RTD("tos.rtd",,K$2,"."&$A$2&$J$1&"P"&$A11)) -> -1359 | L11: =IF(RTD("tos.rtd",,L$2,"."&$A$2&$L$1&"C"&$A11)="N/A",0,RTD("tos.rtd",,L$2,"."&$A$2&$L$1&"C"&$A11)) -> 4965 | M11: =-IF(RTD("tos.rtd",,M$2,"."&$A$2&$L$1&"P"&$A11)="N/A",0,RTD("tos.rtd",,M$2,"."&$A$2&$L$1&"P"&$A11)) -> -4539 | N11: =SUM(H11:M11) -> 7775 | O11: =+A11 -> 682 | P11: =IF(RTD("tos.rtd",,P$2,"."&$A$2&$H$1&"C"&$A11)="N/A",0,RTD("tos.rtd",,P$2,"."&$A$2&$H$1&"C"&$A11)) -> 12001 | Q11: =-IF(RTD("tos.rtd",,Q$2,"."&$A$2&$H$1&"P"&$A11)="N/A",0,RTD("tos.rtd",,Q$2,"."&$A$2&$H$1&"P"&$A11)) -> -81 | R11: =IF(RTD("tos.rtd",,R$2,"."&$A$2&$J$1&"C"&$A11)="N/A",0,RTD("tos.rtd",,R$2,"."&$A$2&$J$1&"C"&$A11)) -> 4763 | S11: =-IF(RTD("tos.rtd",,S$2,"."&$A$2&$J$1&"P"&$A11)="N/A",0,RTD("tos.rtd",,S$2,"."&$A$2&$J$1&"P"&$A11)) -> -331 | T11: =IF(RTD("tos.rtd",,T$2,"."&$A$2&$L$1&"C"&$A11)="N/A",0,RTD("tos.rtd",,T$2,"."&$A$2&$L$1&"C"&$A11)) -> 1613 | U11: =-IF(RTD("tos.rtd",,U$2,"."&$A$2&$L$1&"P"&$A11)="N/A",0,RTD("tos.rtd",,U$2,"."&$A$2&$L$1&"P"&$A11)) -> -450 | V11: =+Hoja2!Y12 -> 21300 | W11: =SUM(P11:V11) -> 38815
A12: =+A11-$A$39 -> 681 | B12: =+IF($A$1="ABS",H12-I12,H12+I12) -> 2291 | C12: =+IF($A$1="ABS",J12-K12,J12+K12) -> 1033 | D12: =+IF($A$1="ABS",L12-M12,L12+M12) -> 1902 | E12: =SUM(B12:D12) -> 5226 | F12: =+$F$3/$A$3*A12 -> 6851.932 | H12: =IF(RTD("tos.rtd",,H$2,"."&$A$2&$H$1&"C"&$A12)="N/A",0,RTD("tos.rtd",,H$2,"."&$A$2&$H$1&"C"&$A12)) -> 2884 | I12: =-IF(RTD("tos.rtd",,I$2,"."&$A$2&$H$1&"P"&$A12)="N/A",0,RTD("tos.rtd",,I$2,"."&$A$2&$H$1&"P"&$A12)) -> -593 | J12: =IF(RTD("tos.rtd",,J$2,"."&$A$2&$J$1&"C"&$A12)="N/A",0,RTD("tos.rtd",,J$2,"."&$A$2&$J$1&"C"&$A12)) -> 1720 | K12: =-IF(RTD("tos.rtd",,K$2,"."&$A$2&$J$1&"P"&$A12)="N/A",0,RTD("tos.rtd",,K$2,"."&$A$2&$J$1&"P"&$A12)) -> -687 | L12: =IF(RTD("tos.rtd",,L$2,"."&$A$2&$L$1&"C"&$A12)="N/A",0,RTD("tos.rtd",,L$2,"."&$A$2&$L$1&"C"&$A12)) -> 3779 | M12: =-IF(RTD("tos.rtd",,M$2,"."&$A$2&$L$1&"P"&$A12)="N/A",0,RTD("tos.rtd",,M$2,"."&$A$2&$L$1&"P"&$A12)) -> -1877 | N12: =SUM(H12:M12) -> 5226 | O12: =+A12 -> 681 | P12: =IF(RTD("tos.rtd",,P$2,"."&$A$2&$H$1&"C"&$A12)="N/A",0,RTD("tos.rtd",,P$2,"."&$A$2&$H$1&"C"&$A12)) -> 15662 | Q12: =-IF(RTD("tos.rtd",,Q$2,"."&$A$2&$H$1&"P"&$A12)="N/A",0,RTD("tos.rtd",,Q$2,"."&$A$2&$H$1&"P"&$A12)) -> -220 | R12: =IF(RTD("tos.rtd",,R$2,"."&$A$2&$J$1&"C"&$A12)="N/A",0,RTD("tos.rtd",,R$2,"."&$A$2&$J$1&"C"&$A12)) -> 3335 | S12: =-IF(RTD("tos.rtd",,S$2,"."&$A$2&$J$1&"P"&$A12)="N/A",0,RTD("tos.rtd",,S$2,"."&$A$2&$J$1&"P"&$A12)) -> -219 | T12: =IF(RTD("tos.rtd",,T$2,"."&$A$2&$L$1&"C"&$A12)="N/A",0,RTD("tos.rtd",,T$2,"."&$A$2&$L$1&"C"&$A12)) -> 1424 | U12: =-IF(RTD("tos.rtd",,U$2,"."&$A$2&$L$1&"P"&$A12)="N/A",0,RTD("tos.rtd",,U$2,"."&$A$2&$L$1&"P"&$A12)) -> -35 | V12: =+Hoja2!Y13 -> 21809 | W12: =SUM(P12:V12) -> 41756
A13: =+A12-$A$39 -> 680 | B13: =+IF($A$1="ABS",H13-I13,H13+I13) -> 7072 | C13: =+IF($A$1="ABS",J13-K13,J13+K13) -> 5161 | D13: =+IF($A$1="ABS",L13-M13,L13+M13) -> 19860 | E13: =SUM(B13:D13) -> 32093 | F13: =+$F$3/$A$3*A13 -> 6841.8704 | H13: =IF(RTD("tos.rtd",,H$2,"."&$A$2&$H$1&"C"&$A13)="N/A",0,RTD("tos.rtd",,H$2,"."&$A$2&$H$1&"C"&$A13)) -> 10150 | I13: =-IF(RTD("tos.rtd",,I$2,"."&$A$2&$H$1&"P"&$A13)="N/A",0,RTD("tos.rtd",,I$2,"."&$A$2&$H$1&"P"&$A13)) -> -3078 | J13: =IF(RTD("tos.rtd",,J$2,"."&$A$2&$J$1&"C"&$A13)="N/A",0,RTD("tos.rtd",,J$2,"."&$A$2&$J$1&"C"&$A13)) -> 8795 | K13: =-IF(RTD("tos.rtd",,K$2,"."&$A$2&$J$1&"P"&$A13)="N/A",0,RTD("tos.rtd",,K$2,"."&$A$2&$J$1&"P"&$A13)) -> -3634 | L13: =IF(RTD("tos.rtd",,L$2,"."&$A$2&$L$1&"C"&$A13)="N/A",0,RTD("tos.rtd",,L$2,"."&$A$2&$L$1&"C"&$A13)) -> 31225 | M13: =-IF(RTD("tos.rtd",,M$2,"."&$A$2&$L$1&"P"&$A13)="N/A",0,RTD("tos.rtd",,M$2,"."&$A$2&$L$1&"P"&$A13)) -> -11365 | N13: =SUM(H13:M13) -> 32093 | O13: =+A13 -> 680 | P13: =IF(RTD("tos.rtd",,P$2,"."&$A$2&$H$1&"C"&$A13)="N/A",0,RTD("tos.rtd",,P$2,"."&$A$2&$H$1&"C"&$A13)) -> 37037 | Q13: =-IF(RTD("tos.rtd",,Q$2,"."&$A$2&$H$1&"P"&$A13)="N/A",0,RTD("tos.rtd",,Q$2,"."&$A$2&$H$1&"P"&$A13)) -> -1436 | R13: =IF(RTD("tos.rtd",,R$2,"."&$A$2&$J$1&"C"&$A13)="N/A",0,RTD("tos.rtd",,R$2,"."&$A$2&$J$1&"C"&$A13)) -> 48542 | S13: =-IF(RTD("tos.rtd",,S$2,"."&$A$2&$J$1&"P"&$A13)="N/A",0,RTD("tos.rtd",,S$2,"."&$A$2&$J$1&"P"&$A13)) -> -1165 | T13: =IF(RTD("tos.rtd",,T$2,"."&$A$2&$L$1&"C"&$A13)="N/A",0,RTD("tos.rtd",,T$2,"."&$A$2&$L$1&"C"&$A13)) -> 16301 | U13: =-IF(RTD("tos.rtd",,U$2,"."&$A$2&$L$1&"P"&$A13)="N/A",0,RTD("tos.rtd",,U$2,"."&$A$2&$L$1&"P"&$A13)) -> -2226 | V13: =+Hoja2!Y14 -> 75942 | W13: =SUM(P13:V13) -> 172995
A14: =+A13-$A$39 -> 679 | B14: =+IF($A$1="ABS",H14-I14,H14+I14) -> -574 | C14: =+IF($A$1="ABS",J14-K14,J14+K14) -> 1063 | D14: =+IF($A$1="ABS",L14-M14,L14+M14) -> -339 | E14: =SUM(B14:D14) -> 150 | F14: =+$F$3/$A$3*A14 -> 6831.8089 | H14: =IF(RTD("tos.rtd",,H$2,"."&$A$2&$H$1&"C"&$A14)="N/A",0,RTD("tos.rtd",,H$2,"."&$A$2&$H$1&"C"&$A14)) -> 2597 | I14: =-IF(RTD("tos.rtd",,I$2,"."&$A$2&$H$1&"P"&$A14)="N/A",0,RTD("tos.rtd",,I$2,"."&$A$2&$H$1&"P"&$A14)) -> -3171 | J14: =IF(RTD("tos.rtd",,J$2,"."&$A$2&$J$1&"C"&$A14)="N/A",0,RTD("tos.rtd",,J$2,"."&$A$2&$J$1&"C"&$A14)) -> 2057 | K14: =-IF(RTD("tos.rtd",,K$2,"."&$A$2&$J$1&"P"&$A14)="N/A",0,RTD("tos.rtd",,K$2,"."&$A$2&$J$1&"P"&$A14)) -> -994 | L14: =IF(RTD("tos.rtd",,L$2,"."&$A$2&$L$1&"C"&$A14)="N/A",0,RTD("tos.rtd",,L$2,"."&$A$2&$L$1&"C"&$A14)) -> 1408 | M14: =-IF(RTD("tos.rtd",,M$2,"."&$A$2&$L$1&"P"&$A14)="N/A",0,RTD("tos.rtd",,M$2,"."&$A$2&$L$1&"P"&$A14)) -> -1747 | N14: =SUM(H14:M14) -> 150 | O14: =+A14 -> 679 | P14: =IF(RTD("tos.rtd",,P$2,"."&$A$2&$H$1&"C"&$A14)="N/A",0,RTD("tos.rtd",,P$2,"."&$A$2&$H$1&"C"&$A14)) -> 20130 | Q14: =-IF(RTD("tos.rtd",,Q$2,"."&$A$2&$H$1&"P"&$A14)="N/A",0,RTD("tos.rtd",,Q$2,"."&$A$2&$H$1&"P"&$A14)) -> -3033 | R14: =IF(RTD("tos.rtd",,R$2,"."&$A$2&$J$1&"C"&$A14)="N/A",0,RTD("tos.rtd",,R$2,"."&$A$2&$J$1&"C"&$A14)) -> 6367 | S14: =-IF(RTD("tos.rtd",,S$2,"."&$A$2&$J$1&"P"&$A14)="N/A",0,RTD("tos.rtd",,S$2,"."&$A$2&$J$1&"P"&$A14)) -> -288 | T14: =IF(RTD("tos.rtd",,T$2,"."&$A$2&$L$1&"C"&$A14)="N/A",0,RTD("tos.rtd",,T$2,"."&$A$2&$L$1&"C"&$A14)) -> 1375 | U14: =-IF(RTD("tos.rtd",,U$2,"."&$A$2&$L$1&"P"&$A14)="N/A",0,RTD("tos.rtd",,U$2,"."&$A$2&$L$1&"P"&$A14)) -> -1102 | V14: =+Hoja2!Y15 -> 23195 | W14: =SUM(P14:V14) -> 46644
A15: =+A14-$A$39 -> 678 | B15: =+IF($A$1="ABS",H15-I15,H15+I15) -> 1236 | C15: =+IF($A$1="ABS",J15-K15,J15+K15) -> 1975 | D15: =+IF($A$1="ABS",L15-M15,L15+M15) -> 235 | E15: =SUM(B15:D15) -> 3446 | F15: =+$F$3/$A$3*A15 -> 6821.7473 | H15: =IF(RTD("tos.rtd",,H$2,"."&$A$2&$H$1&"C"&$A15)="N/A",0,RTD("tos.rtd",,H$2,"."&$A$2&$H$1&"C"&$A15)) -> 3224 | I15: =-IF(RTD("tos.rtd",,I$2,"."&$A$2&$H$1&"P"&$A15)="N/A",0,RTD("tos.rtd",,I$2,"."&$A$2&$H$1&"P"&$A15)) -> -1988 | J15: =IF(RTD("tos.rtd",,J$2,"."&$A$2&$J$1&"C"&$A15)="N/A",0,RTD("tos.rtd",,J$2,"."&$A$2&$J$1&"C"&$A15)) -> 3417 | K15: =-IF(RTD("tos.rtd",,K$2,"."&$A$2&$J$1&"P"&$A15)="N/A",0,RTD("tos.rtd",,K$2,"."&$A$2&$J$1&"P"&$A15)) -> -1442 | L15: =IF(RTD("tos.rtd",,L$2,"."&$A$2&$L$1&"C"&$A15)="N/A",0,RTD("tos.rtd",,L$2,"."&$A$2&$L$1&"C"&$A15)) -> 4807 | M15: =-IF(RTD("tos.rtd",,M$2,"."&$A$2&$L$1&"P"&$A15)="N/A",0,RTD("tos.rtd",,M$2,"."&$A$2&$L$1&"P"&$A15)) -> -4572 | N15: =SUM(H15:M15) -> 3446 | O15: =+A15 -> 678 | P15: =IF(RTD("tos.rtd",,P$2,"."&$A$2&$H$1&"C"&$A15)="N/A",0,RTD("tos.rtd",,P$2,"."&$A$2&$H$1&"C"&$A15)) -> 16546 | Q15: =-IF(RTD("tos.rtd",,Q$2,"."&$A$2&$H$1&"P"&$A15)="N/A",0,RTD("tos.rtd",,Q$2,"."&$A$2&$H$1&"P"&$A15)) -> -1266 | R15: =IF(RTD("tos.rtd",,R$2,"."&$A$2&$J$1&"C"&$A15)="N/A",0,RTD("tos.rtd",,R$2,"."&$A$2&$J$1&"C"&$A15)) -> 3636 | S15: =-IF(RTD("tos.rtd",,S$2,"."&$A$2&$J$1&"P"&$A15)="N/A",0,RTD("tos.rtd",,S$2,"."&$A$2&$J$1&"P"&$A15)) -> -401 | T15: =IF(RTD("tos.rtd",,T$2,"."&$A$2&$L$1&"C"&$A15)="N/A",0,RTD("tos.rtd",,T$2,"."&$A$2&$L$1&"C"&$A15)) -> 1992 | U15: =-IF(RTD("tos.rtd",,U$2,"."&$A$2&$L$1&"P"&$A15)="N/A",0,RTD("tos.rtd",,U$2,"."&$A$2&$L$1&"P"&$A15)) -> -1134 | V15: =+Hoja2!Y16 -> 23641 | W15: =SUM(P15:V15) -> 43014
A16: =+A15-$A$39 -> 677 | B16: =+IF($A$1="ABS",H16-I16,H16+I16) -> 1255 | C16: =+IF($A$1="ABS",J16-K16,J16+K16) -> -4303 | D16: =+IF($A$1="ABS",L16-M16,L16+M16) -> 332 | E16: =SUM(B16:D16) -> -2716 | F16: =+$F$3/$A$3*A16 -> 6811.6857 | H16: =IF(RTD("tos.rtd",,H$2,"."&$A$2&$H$1&"C"&$A16)="N/A",0,RTD("tos.rtd",,H$2,"."&$A$2&$H$1&"C"&$A16)) -> 3018 | I16: =-IF(RTD("tos.rtd",,I$2,"."&$A$2&$H$1&"P"&$A16)="N/A",0,RTD("tos.rtd",,I$2,"."&$A$2&$H$1&"P"&$A16)) -> -1763 | J16: =IF(RTD("tos.rtd",,J$2,"."&$A$2&$J$1&"C"&$A16)="N/A",0,RTD("tos.rtd",,J$2,"."&$A$2&$J$1&"C"&$A16)) -> 3754 | K16: =-IF(RTD("tos.rtd",,K$2,"."&$A$2&$J$1&"P"&$A16)="N/A",0,RTD("tos.rtd",,K$2,"."&$A$2&$J$1&"P"&$A16)) -> -8057 | L16: =IF(RTD("tos.rtd",,L$2,"."&$A$2&$L$1&"C"&$A16)="N/A",0,RTD("tos.rtd",,L$2,"."&$A$2&$L$1&"C"&$A16)) -> 2936 | M16: =-IF(RTD("tos.rtd",,M$2,"."&$A$2&$L$1&"P"&$A16)="N/A",0,RTD("tos.rtd",,M$2,"."&$A$2&$L$1&"P"&$A16)) -> -2604 | N16: =SUM(H16:M16) -> -2716 | O16: =+A16 -> 677 | P16: =IF(RTD("tos.rtd",,P$2,"."&$A$2&$H$1&"C"&$A16)="N/A",0,RTD("tos.rtd",,P$2,"."&$A$2&$H$1&"C"&$A16)) -> 23860 | Q16: =-IF(RTD("tos.rtd",,Q$2,"."&$A$2&$H$1&"P"&$A16)="N/A",0,RTD("tos.rtd",,Q$2,"."&$A$2&$H$1&"P"&$A16)) -> -2215 | R16: =IF(RTD("tos.rtd",,R$2,"."&$A$2&$J$1&"C"&$A16)="N/A",0,RTD("tos.rtd",,R$2,"."&$A$2&$J$1&"C"&$A16)) -> 4775 | S16: =-IF(RTD("tos.rtd",,S$2,"."&$A$2&$J$1&"P"&$A16)="N/A",0,RTD("tos.rtd",,S$2,"."&$A$2&$J$1&"P"&$A16)) -> -2289 | T16: =IF(RTD("tos.rtd",,T$2,"."&$A$2&$L$1&"C"&$A16)="N/A",0,RTD("tos.rtd",,T$2,"."&$A$2&$L$1&"C"&$A16)) -> 1831 | U16: =-IF(RTD("tos.rtd",,U$2,"."&$A$2&$L$1&"P"&$A16)="N/A",0,RTD("tos.rtd",,U$2,"."&$A$2&$L$1&"P"&$A16)) -> -175 | V16: =+Hoja2!Y17 -> 38616 | W16: =SUM(P16:V16) -> 64403
... A38: =+A37-$A$39 -> 655 | B38: =+IF($A$1="ABS",H38-I38,H38+I38) -> -1763 | C38: =+IF($A$1="ABS",J38-K38,J38+K38) -> -3746 | D38: =+IF($A$1="ABS",L38-M38,L38+M38) -> -22188 | E38: =SUM(B38:D38) -> -27697 | F38: =+$F$3/$A$3*A38 -> 6590.3311 | H38: =IF(RTD("tos.rtd",,H$2,"."&$A$2&$H$1&"C"&$A38)="N/A",0,RTD("tos.rtd",,H$2,"."&$A$2&$H$1&"C"&$A38)) -> 36 | I38: =-IF(RTD("tos.rtd",,I$2,"."&$A$2&$H$1&"P"&$A38)="N/A",0,RTD("tos.rtd",,I$2,"."&$A$2&$H$1&"P"&$A38)) -> -1799 | J38: =IF(RTD("tos.rtd",,J$2,"."&$A$2&$J$1&"C"&$A38)="N/A",0,RTD("tos.rtd",,J$2,"."&$A$2&$J$1&"C"&$A38)) -> 323 | K38: =-IF(RTD("tos.rtd",,K$2,"."&$A$2&$J$1&"P"&$A38)="N/A",0,RTD("tos.rtd",,K$2,"."&$A$2&$J$1&"P"&$A38)) -> -4069 | L38: =IF(RTD("tos.rtd",,L$2,"."&$A$2&$L$1&"C"&$A38)="N/A",0,RTD("tos.rtd",,L$2,"."&$A$2&$L$1&"C"&$A38)) -> 3824 | M38: =-IF(RTD("tos.rtd",,M$2,"."&$A$2&$L$1&"P"&$A38)="N/A",0,RTD("tos.rtd",,M$2,"."&$A$2&$L$1&"P"&$A38)) -> -26012 | N38: =SUM(H38:M38) -> -27697 | O38: =+A38 -> 655 | P38: =IF(RTD("tos.rtd",,P$2,"."&$A$2&$H$1&"C"&$A38)="N/A",0,RTD("tos.rtd",,P$2,"."&$A$2&$H$1&"C"&$A38)) -> 600 | Q38: =-IF(RTD("tos.rtd",,Q$2,"."&$A$2&$H$1&"P"&$A38)="N/A",0,RTD("tos.rtd",,Q$2,"."&$A$2&$H$1&"P"&$A38)) -> -26191 | R38: =IF(RTD("tos.rtd",,R$2,"."&$A$2&$J$1&"C"&$A38)="N/A",0,RTD("tos.rtd",,R$2,"."&$A$2&$J$1&"C"&$A38)) -> 421 | S38: =-IF(RTD("tos.rtd",,S$2,"."&$A$2&$J$1&"P"&$A38)="N/A",0,RTD("tos.rtd",,S$2,"."&$A$2&$J$1&"P"&$A38)) -> -13548 | T38: =IF(RTD("tos.rtd",,T$2,"."&$A$2&$L$1&"C"&$A38)="N/A",0,RTD("tos.rtd",,T$2,"."&$A$2&$L$1&"C"&$A38)) -> 340 | U38: =-IF(RTD("tos.rtd",,U$2,"."&$A$2&$L$1&"P"&$A38)="N/A",0,RTD("tos.rtd",,U$2,"."&$A$2&$L$1&"P"&$A38)) -> -15140 | V38: =+Hoja2!Y39 -> -47281 | W38: =SUM(P38:V38) -> -100799
A39: 1 | B39: =MAX(B4:B38)/2 -> 4701.5 | C39: =MAX(C4:C38)/2 -> 2580.5 | D39: =MAX(D4:D38)/2 -> 9930 | E39: =MAX(E4:E38)/2 -> 16046.5 | H39: CALL | I39: PUTS | J39: CALL | K39: PUTS | L39: CALL | M39: PUTS | P39: CALL | Q39: PUTS | R39: CALL | S39: PUTS | T39: CALL | U39: PUTS | W39: =MIN(W4:W38) -> -225535
A40: =RTD("tos.rtd", ,"MARK", A2) -> 672.36 | E40: =+F3/F40 -> 669.63484 | F40: =6011/595 -> 10.102521
A41: =10/657*100 -> 1.52207 | B41: 45890 | E41: =+F44/E42 -> 607.99907
A42: =RTD("tos.rtd", ,"MARK", A43) -> 611.9 | B42: 45971 | C42: 45975 | D42: 45982 | E42: =21783/525 -> 41.491429 | F42: =+[2]Sheet1!$AD$2 -> 562.23707 | H42: =+B43 -> 251110 | J42: =+C43 -> 251114 | L42: =+D43 -> 251121 | P42: =+H42 -> 251110 | Q42: =+I42 -> 0 | R42: =+J42 -> 251114 | S42: =+K42 -> 0 | T42: =+L42 -> 251121 | U42: =+M42 -> 0 | W42: =MAX(W45:W79) -> 116195
A43: QQQ | B43: =+B$2 -> 251110 | C43: =+C2 -> 251114 | D43: =+D2 -> 251121 | F43: /NQ:XCME | H43: OPEN_INT | I43: OPEN_INT | J43: OPEN_INT | K43: OPEN_INT | L43: OPEN_INT | M43: OPEN_INT | N43: NET OI | P43: VOLUME | Q43: VOLUME | R43: VOLUME | S43: VOLUME | T43: VOLUME | U43: VOLUME | W43: NET VOL
A44: =+A42 -> 611.9 | B44: =+H44/I44 -> -0.70412896 | C44: =+J44/K44 -> -0.21749029 | D44: =+L44/M44 -> -0.64063308 | E44: 0 | F44: =RTD("tos.rtd", ,"MARK", F43) -> 25226.75 | H44: =SUM(H45:H79) -> 40536 | I44: =SUM(I45:I79) -> -57569 | J44: =SUM(J45:J79) -> 47576 | K44: =SUM(K45:K79) -> -218750 | L44: =SUM(L45:L79) -> 199431 | M44: =SUM(M45:M79) -> -311303 | N44: =SUM(N45:N79) -> -300079 | O44: 0 | P44: =SUM(P45:P79) -> 506505 | Q44: =SUM(Q45:Q79) -> -374271 | R44: =SUM(R45:R79) -> 122229 | S44: =SUM(S45:S79) -> -158098 | T44: =SUM(T45:T79) -> 64066 | U44: =SUM(U45:U79) -> -111429 | W44: =SUM(W45:W79) -> 253108
A45: =ROUND(A44/$A$39,0)*$A$39+17*$A$39 -> 629 | B45: =+IF($A$1="ABS",H45-I45,H45+I45) -> 852 | C45: =+IF($A$1="ABS",J45-K45,J45+K45) -> -429 | D45: =+IF($A$1="ABS",L45-M45,L45+M45) -> -5217 | E45: =SUM(B45:D45) -> -4794 | F45: =+$F$44/$A$44*A45 -> 25931.73 | H45: =IF(RTD("tos.rtd",,H$43,"."&$A$43&$H$42&"C"&$A45)="N/A",0,RTD("tos.rtd",,H$43,"."&$A$43&$H$42&"C"&$A45)) -> 1154 | I45: =-IF(RTD("tos.rtd",,I$43,"."&$A$43&$H$42&"P"&$A45)="N/A",0,RTD("tos.rtd",,I$43,"."&$A$43&$H$42&"P"&$A45)) -> -302 | J45: =IF(RTD("tos.rtd",,J$2,"."&$A$43&$J$1&"C"&$A45)="N/A",0,RTD("tos.rtd",,J$2,"."&$A$43&$J$1&"C"&$A45)) -> 612 | K45: =-IF(RTD("tos.rtd",,K$2,"."&$A$43&$J$1&"P"&$A45)="N/A",0,RTD("tos.rtd",,K$2,"."&$A$43&$J$1&"P"&$A45)) -> -1041 | L45: =IF(RTD("tos.rtd",,L$2,"."&$A$43&$L$1&"C"&$A45)="N/A",0,RTD("tos.rtd",,L$2,"."&$A$43&$L$1&"C"&$A45)) -> 3032 | M45: =-IF(RTD("tos.rtd",,M$2,"."&$A$43&$L$1&"P"&$A45)="N/A",0,RTD("tos.rtd",,M$2,"."&$A$43&$L$1&"P"&$A45)) -> -8249 | N45: =SUM(H45:M45) -> -4794 | O45: =+A45 -> 629 | P45: =IF(RTD("tos.rtd",,P$43,"."&$A$43&$H$42&"C"&$A45)="N/A",0,RTD("tos.rtd",,P$43,"."&$A$43&$H$42&"C"&$A45)) -> 1380 | Q45: =-IF(RTD("tos.rtd",,Q$43,"."&$A$43&$H$42&"P"&$A45)="N/A",0,RTD("tos.rtd",,Q$43,"."&$A$43&$H$42&"P"&$A45)) -> -7 | R45: =IF(RTD("tos.rtd",,R$2,"."&$A$43&$J$1&"C"&$A45)="N/A",0,RTD("tos.rtd",,R$2,"."&$A$43&$J$1&"C"&$A45)) -> 793 | S45: =-IF(RTD("tos.rtd",,S$2,"."&$A$43&$J$1&"P"&$A45)="N/A",0,RTD("tos.rtd",,S$2,"."&$A$43&$J$1&"P"&$A45)) -> -60 | T45: =IF(RTD("tos.rtd",,T$2,"."&$A$43&$L$1&"C"&$A45)="N/A",0,RTD("tos.rtd",,T$2,"."&$A$43&$L$1&"C"&$A45)) -> 2460 | U45: =-IF(RTD("tos.rtd",,U$2,"."&$A$43&$L$1&"P"&$A45)="N/A",0,RTD("tos.rtd",,U$2,"."&$A$43&$L$1&"P"&$A45)) -> -16 | V45: =+Hoja2!Y46 -> 2713 | W45: =SUM(P45:V45) -> 7263
A46: =+A45-$A$39 -> 628 | B46: =+IF($A$1="ABS",H46-I46,H46+I46) -> 1158 | C46: =+IF($A$1="ABS",J46-K46,J46+K46) -> 460 | D46: =+IF($A$1="ABS",L46-M46,L46+M46) -> 794 | E46: =SUM(B46:D46) -> 2412 | F46: =+$F$44/$A$44*A46 -> 25890.503 | H46: =IF(RTD("tos.rtd",,H$43,"."&$A$43&$H$42&"C"&$A46)="N/A",0,RTD("tos.rtd",,H$43,"."&$A$43&$H$42&"C"&$A46)) -> 1366 | I46: =-IF(RTD("tos.rtd",,I$43,"."&$A$43&$H$42&"P"&$A46)="N/A",0,RTD("tos.rtd",,I$43,"."&$A$43&$H$42&"P"&$A46)) -> -208 | J46: =IF(RTD("tos.rtd",,J$2,"."&$A$43&$J$1&"C"&$A46)="N/A",0,RTD("tos.rtd",,J$2,"."&$A$43&$J$1&"C"&$A46)) -> 2028 | K46: =-IF(RTD("tos.rtd",,K$2,"."&$A$43&$J$1&"P"&$A46)="N/A",0,RTD("tos.rtd",,K$2,"."&$A$43&$J$1&"P"&$A46)) -> -1568 | L46: =IF(RTD("tos.rtd",,L$2,"."&$A$43&$L$1&"C"&$A46)="N/A",0,RTD("tos.rtd",,L$2,"."&$A$43&$L$1&"C"&$A46)) -> 2003 | M46: =-IF(RTD("tos.rtd",,M$2,"."&$A$43&$L$1&"P"&$A46)="N/A",0,RTD("tos.rtd",,M$2,"."&$A$43&$L$1&"P"&$A46)) -> -1209 | N46: =SUM(H46:M46) -> 2412 | O46: =+A46 -> 628 | P46: =IF(RTD("tos.rtd",,P$43,"."&$A$43&$H$42&"C"&$A46)="N/A",0,RTD("tos.rtd",,P$43,"."&$A$43&$H$42&"C"&$A46)) -> 1090 | Q46: =-IF(RTD("tos.rtd",,Q$43,"."&$A$43&$H$42&"P"&$A46)="N/A",0,RTD("tos.rtd",,Q$43,"."&$A$43&$H$42&"P"&$A46)) -> -110 | R46: =IF(RTD("tos.rtd",,R$2,"."&$A$43&$J$1&"C"&$A46)="N/A",0,RTD("tos.rtd",,R$2,"."&$A$43&$J$1&"C"&$A46)) -> 866 | S46: =-IF(RTD("tos.rtd",,S$2,"."&$A$43&$J$1&"P"&$A46)="N/A",0,RTD("tos.rtd",,S$2,"."&$A$43&$J$1&"P"&$A46)) -> -109 | T46: =IF(RTD("tos.rtd",,T$2,"."&$A$43&$L$1&"C"&$A46)="N/A",0,RTD("tos.rtd",,T$2,"."&$A$43&$L$1&"C"&$A46)) -> 453 | U46: =-IF(RTD("tos.rtd",,U$2,"."&$A$43&$L$1&"P"&$A46)="N/A",0,RTD("tos.rtd",,U$2,"."&$A$43&$L$1&"P"&$A46)) -> -142 | V46: =+Hoja2!Y47 -> 1980 | W46: =SUM(P46:V46) -> 4028
A47: =+A46-$A$39 -> 627 | B47: =+IF($A$1="ABS",H47-I47,H47+I47) -> 496 | C47: =+IF($A$1="ABS",J47-K47,J47+K47) -> -512 | D47: =+IF($A$1="ABS",L47-M47,L47+M47) -> 2137 | E47: =SUM(B47:D47) -> 2121 | F47: =+$F$44/$A$44*A47 -> 25849.276 | H47: =IF(RTD("tos.rtd",,H$43,"."&$A$43&$H$42&"C"&$A47)="N/A",0,RTD("tos.rtd",,H$43,"."&$A$43&$H$42&"C"&$A47)) -> 1108 | I47: =-IF(RTD("tos.rtd",,I$43,"."&$A$43&$H$42&"P"&$A47)="N/A",0,RTD("tos.rtd",,I$43,"."&$A$43&$H$42&"P"&$A47)) -> -612 | J47: =IF(RTD("tos.rtd",,J$2,"."&$A$43&$J$1&"C"&$A47)="N/A",0,RTD("tos.rtd",,J$2,"."&$A$43&$J$1&"C"&$A47)) -> 1482 | K47: =-IF(RTD("tos.rtd",,K$2,"."&$A$43&$J$1&"P"&$A47)="N/A",0,RTD("tos.rtd",,K$2,"."&$A$43&$J$1&"P"&$A47)) -> -1994 | L47: =IF(RTD("tos.rtd",,L$2,"."&$A$43&$L$1&"C"&$A47)="N/A",0,RTD("tos.rtd",,L$2,"."&$A$43&$L$1&"C"&$A47)) -> 4109 | M47: =-IF(RTD("tos.rtd",,M$2,"."&$A$43&$L$1&"P"&$A47)="N/A",0,RTD("tos.rtd",,M$2,"."&$A$43&$L$1&"P"&$A47)) -> -1972 | N47: =SUM(H47:M47) -> 2121 | O47: =+A47 -> 627 | P47: =IF(RTD("tos.rtd",,P$43,"."&$A$43&$H$42&"C"&$A47)="N/A",0,RTD("tos.rtd",,P$43,"."&$A$43&$H$42&"C"&$A47)) -> 956 | Q47: =-IF(RTD("tos.rtd",,Q$43,"."&$A$43&$H$42&"P"&$A47)="N/A",0,RTD("tos.rtd",,Q$43,"."&$A$43&$H$42&"P"&$A47)) -> -221 | R47: =IF(RTD("tos.rtd",,R$2,"."&$A$43&$J$1&"C"&$A47)="N/A",0,RTD("tos.rtd",,R$2,"."&$A$43&$J$1&"C"&$A47)) -> 1725 | S47: =-IF(RTD("tos.rtd",,S$2,"."&$A$43&$J$1&"P"&$A47)="N/A",0,RTD("tos.rtd",,S$2,"."&$A$43&$J$1&"P"&$A47)) -> -251 | T47: =IF(RTD("tos.rtd",,T$2,"."&$A$43&$L$1&"C"&$A47)="N/A",0,RTD("tos.rtd",,T$2,"."&$A$43&$L$1&"C"&$A47)) -> 378 | U47: =-IF(RTD("tos.rtd",,U$2,"."&$A$43&$L$1&"P"&$A47)="N/A",0,RTD("tos.rtd",,U$2,"."&$A$43&$L$1&"P"&$A47)) -> -129 | V47: =+Hoja2!Y48 -> 2515 | W47: =SUM(P47:V47) -> 4973
A48: =+A47-$A$39 -> 626 | B48: =+IF($A$1="ABS",H48-I48,H48+I48) -> 2281 | C48: =+IF($A$1="ABS",J48-K48,J48+K48) -> -117 | D48: =+IF($A$1="ABS",L48-M48,L48+M48) -> -92 | E48: =SUM(B48:D48) -> 2072 | F48: =+$F$44/$A$44*A48 -> 25808.05 | H48: =IF(RTD("tos.rtd",,H$43,"."&$A$43&$H$42&"C"&$A48)="N/A",0,RTD("tos.rtd",,H$43,"."&$A$43&$H$42&"C"&$A48)) -> 2635 | I48: =-IF(RTD("tos.rtd",,I$43,"."&$A$43&$H$42&"P"&$A48)="N/A",0,RTD("tos.rtd",,I$43,"."&$A$43&$H$42&"P"&$A48)) -> -354 | J48: =IF(RTD("tos.rtd",,J$2,"."&$A$43&$J$1&"C"&$A48)="N/A",0,RTD("tos.rtd",,J$2,"."&$A$43&$J$1&"C"&$A48)) -> 838 | K48: =-IF(RTD("tos.rtd",,K$2,"."&$A$43&$J$1&"P"&$A48)="N/A",0,RTD("tos.rtd",,K$2,"."&$A$43&$J$1&"P"&$A48)) -> -955 | L48: =IF(RTD("tos.rtd",,L$2,"."&$A$43&$L$1&"C"&$A48)="N/A",0,RTD("tos.rtd",,L$2,"."&$A$43&$L$1&"C"&$A48)) -> 1653 | M48: =-IF(RTD("tos.rtd",,M$2,"."&$A$43&$L$1&"P"&$A48)="N/A",0,RTD("tos.rtd",,M$2,"."&$A$43&$L$1&"P"&$A48)) -> -1745 | N48: =SUM(H48:M48) -> 2072 | O48: =+A48 -> 626 | P48: =IF(RTD("tos.rtd",,P$43,"."&$A$43&$H$42&"C"&$A48)="N/A",0,RTD("tos.rtd",,P$43,"."&$A$43&$H$42&"C"&$A48)) -> 2298 | Q48: =-IF(RTD("tos.rtd",,Q$43,"."&$A$43&$H$42&"P"&$A48)="N/A",0,RTD("tos.rtd",,Q$43,"."&$A$43&$H$42&"P"&$A48)) -> -155 | R48: =IF(RTD("tos.rtd",,R$2,"."&$A$43&$J$1&"C"&$A48)="N/A",0,RTD("tos.rtd",,R$2,"."&$A$43&$J$1&"C"&$A48)) -> 943 | S48: =-IF(RTD("tos.rtd",,S$2,"."&$A$43&$J$1&"P"&$A48)="N/A",0,RTD("tos.rtd",,S$2,"."&$A$43&$J$1&"P"&$A48)) -> -132 | T48: =IF(RTD("tos.rtd",,T$2,"."&$A$43&$L$1&"C"&$A48)="N/A",0,RTD("tos.rtd",,T$2,"."&$A$43&$L$1&"C"&$A48)) -> 601 | U48: =-IF(RTD("tos.rtd",,U$2,"."&$A$43&$L$1&"P"&$A48)="N/A",0,RTD("tos.rtd",,U$2,"."&$A$43&$L$1&"P"&$A48)) -> -104 | V48: =+Hoja2!Y49 -> 4702 | W48: =SUM(P48:V48) -> 8153
A49: =+A48-$A$39 -> 625 | B49: =+IF($A$1="ABS",H49-I49,H49+I49) -> -1936 | C49: =+IF($A$1="ABS",J49-K49,J49+K49) -> -13703 | D49: =+IF($A$1="ABS",L49-M49,L49+M49) -> 5922 | E49: =SUM(B49:D49) -> -9717 | F49: =+$F$44/$A$44*A49 -> 25766.823 | H49: =IF(RTD("tos.rtd",,H$43,"."&$A$43&$H$42&"C"&$A49)="N/A",0,RTD("tos.rtd",,H$43,"."&$A$43&$H$42&"C"&$A49)) -> 5999 | I49: =-IF(RTD("tos.rtd",,I$43,"."&$A$43&$H$42&"P"&$A49)="N/A",0,RTD("tos.rtd",,I$43,"."&$A$43&$H$42&"P"&$A49)) -> -7935 | J49: =IF(RTD("tos.rtd",,J$2,"."&$A$43&$J$1&"C"&$A49)="N/A",0,RTD("tos.rtd",,J$2,"."&$A$43&$J$1&"C"&$A49)) -> 6844 | K49: =-IF(RTD("tos.rtd",,K$2,"."&$A$43&$J$1&"P"&$A49)="N/A",0,RTD("tos.rtd",,K$2,"."&$A$43&$J$1&"P"&$A49)) -> -20547 | L49: =IF(RTD("tos.rtd",,L$2,"."&$A$43&$L$1&"C"&$A49)="N/A",0,RTD("tos.rtd",,L$2,"."&$A$43&$L$1&"C"&$A49)) -> 26148 | M49: =-IF(RTD("tos.rtd",,M$2,"."&$A$43&$L$1&"P"&$A49)="N/A",0,RTD("tos.rtd",,M$2,"."&$A$43&$L$1&"P"&$A49)) -> -20226 | N49: =SUM(H49:M49) -> -9717 | O49: =+A49 -> 625 | P49: =IF(RTD("tos.rtd",,P$43,"."&$A$43&$H$42&"C"&$A49)="N/A",0,RTD("tos.rtd",,P$43,"."&$A$43&$H$42&"C"&$A49)) -> 6604 | Q49: =-IF(RTD("tos.rtd",,Q$43,"."&$A$43&$H$42&"P"&$A49)="N/A",0,RTD("tos.rtd",,Q$43,"."&$A$43&$H$42&"P"&$A49)) -> -258 | R49: =IF(RTD("tos.rtd",,R$2,"."&$A$43&$J$1&"C"&$A49)="N/A",0,RTD("tos.rtd",,R$2,"."&$A$43&$J$1&"C"&$A49)) -> 6311 | S49: =-IF(RTD("tos.rtd",,S$2,"."&$A$43&$J$1&"P"&$A49)="N/A",0,RTD("tos.rtd",,S$2,"."&$A$43&$J$1&"P"&$A49)) -> -1607 | T49: =IF(RTD("tos.rtd",,T$2,"."&$A$43&$L$1&"C"&$A49)="N/A",0,RTD("tos.rtd",,T$2,"."&$A$43&$L$1&"C"&$A49)) -> 8539 | U49: =-IF(RTD("tos.rtd",,U$2,"."&$A$43&$L$1&"P"&$A49)="N/A",0,RTD("tos.rtd",,U$2,"."&$A$43&$L$1&"P"&$A49)) -> -817 | V49: =+Hoja2!Y50 -> 20802 | W49: =SUM(P49:V49) -> 39574
A50: =+A49-$A$39 -> 624 | B50: =+IF($A$1="ABS",H50-I50,H50+I50) -> 217 | C50: =+IF($A$1="ABS",J50-K50,J50+K50) -> -364 | D50: =+IF($A$1="ABS",L50-M50,L50+M50) -> -872 | E50: =SUM(B50:D50) -> -1019 | F50: =+$F$44/$A$44*A50 -> 25725.596 | H50: =IF(RTD("tos.rtd",,H$43,"."&$A$43&$H$42&"C"&$A50)="N/A",0,RTD("tos.rtd",,H$43,"."&$A$43&$H$42&"C"&$A50)) -> 965 | I50: =-IF(RTD("tos.rtd",,I$43,"."&$A$43&$H$42&"P"&$A50)="N/A",0,RTD("tos.rtd",,I$43,"."&$A$43&$H$42&"P"&$A50)) -> -748 | J50: =IF(RTD("tos.rtd",,J$2,"."&$A$43&$J$1&"C"&$A50)="N/A",0,RTD("tos.rtd",,J$2,"."&$A$43&$J$1&"C"&$A50)) -> 1098 | K50: =-IF(RTD("tos.rtd",,K$2,"."&$A$43&$J$1&"P"&$A50)="N/A",0,RTD("tos.rtd",,K$2,"."&$A$43&$J$1&"P"&$A50)) -> -1462 | L50: =IF(RTD("tos.rtd",,L$2,"."&$A$43&$L$1&"C"&$A50)="N/A",0,RTD("tos.rtd",,L$2,"."&$A$43&$L$1&"C"&$A50)) -> 2338 | M50: =-IF(RTD("tos.rtd",,M$2,"."&$A$43&$L$1&"P"&$A50)="N/A",0,RTD("tos.rtd",,M$2,"."&$A$43&$L$1&"P"&$A50)) -> -3210 | N50: =SUM(H50:M50) -> -1019 | O50: =+A50 -> 624 | P50: =IF(RTD("tos.rtd",,P$43,"."&$A$43&$H$42&"C"&$A50)="N/A",0,RTD("tos.rtd",,P$43,"."&$A$43&$H$42&"C"&$A50)) -> 2005 | Q50: =-IF(RTD("tos.rtd",,Q$43,"."&$A$43&$H$42&"P"&$A50)="N/A",0,RTD("tos.rtd",,Q$43,"."&$A$43&$H$42&"P"&$A50)) -> -180 | R50: =IF(RTD("tos.rtd",,R$2,"."&$A$43&$J$1&"C"&$A50)="N/A",0,RTD("tos.rtd",,R$2,"."&$A$43&$J$1&"C"&$A50)) -> 1023 | S50: =-IF(RTD("tos.rtd",,S$2,"."&$A$43&$J$1&"P"&$A50)="N/A",0,RTD("tos.rtd",,S$2,"."&$A$43&$J$1&"P"&$A50)) -> -60 | T50: =IF(RTD("tos.rtd",,T$2,"."&$A$43&$L$1&"C"&$A50)="N/A",0,RTD("tos.rtd",,T$2,"."&$A$43&$L$1&"C"&$A50)) -> 892 | U50: =-IF(RTD("tos.rtd",,U$2,"."&$A$43&$L$1&"P"&$A50)="N/A",0,RTD("tos.rtd",,U$2,"."&$A$43&$L$1&"P"&$A50)) -> -1087 | V50: =+Hoja2!Y51 -> 14552 | W50: =SUM(P50:V50) -> 17145
A51: =+A50-$A$39 -> 623 | B51: =+IF($A$1="ABS",H51-I51,H51+I51) -> 341 | C51: =+IF($A$1="ABS",J51-K51,J51+K51) -> -2476 | D51: =+IF($A$1="ABS",L51-M51,L51+M51) -> -194 | E51: =SUM(B51:D51) -> -2329 | F51: =+$F$44/$A$44*A51 -> 25684.369 | H51: =IF(RTD("tos.rtd",,H$43,"."&$A$43&$H$42&"C"&$A51)="N/A",0,RTD("tos.rtd",,H$43,"."&$A$43&$H$42&"C"&$A51)) -> 1224 | I51: =-IF(RTD("tos.rtd",,I$43,"."&$A$43&$H$42&"P"&$A51)="N/A",0,RTD("tos.rtd",,I$43,"."&$A$43&$H$42&"P"&$A51)) -> -883 | J51: =IF(RTD("tos.rtd",,J$2,"."&$A$43&$J$1&"C"&$A51)="N/A",0,RTD("tos.rtd",,J$2,"."&$A$43&$J$1&"C"&$A51)) -> 940 | K51: =-IF(RTD("tos.rtd",,K$2,"."&$A$43&$J$1&"P"&$A51)="N/A",0,RTD("tos.rtd",,K$2,"."&$A$43&$J$1&"P"&$A51)) -> -3416 | L51: =IF(RTD("tos.rtd",,L$2,"."&$A$43&$L$1&"C"&$A51)="N/A",0,RTD("tos.rtd",,L$2,"."&$A$43&$L$1&"C"&$A51)) -> 5889 | M51: =-IF(RTD("tos.rtd",,M$2,"."&$A$43&$L$1&"P"&$A51)="N/A",0,RTD("tos.rtd",,M$2,"."&$A$43&$L$1&"P"&$A51)) -> -6083 | N51: =SUM(H51:M51) -> -2329 | O51: =+A51 -> 623 | P51: =IF(RTD("tos.rtd",,P$43,"."&$A$43&$H$42&"C"&$A51)="N/A",0,RTD("tos.rtd",,P$43,"."&$A$43&$H$42&"C"&$A51)) -> 3333 | Q51: =-IF(RTD("tos.rtd",,Q$43,"."&$A$43&$H$42&"P"&$A51)="N/A",0,RTD("tos.rtd",,Q$43,"."&$A$43&$H$42&"P"&$A51)) -> -471 | R51: =IF(RTD("tos.rtd",,R$2,"."&$A$43&$J$1&"C"&$A51)="N/A",0,RTD("tos.rtd",,R$2,"."&$A$43&$J$1&"C"&$A51)) -> 1616 | S51: =-IF(RTD("tos.rtd",,S$2,"."&$A$43&$J$1&"P"&$A51)="N/A",0,RTD("tos.rtd",,S$2,"."&$A$43&$J$1&"P"&$A51)) -> -101 | T51: =IF(RTD("tos.rtd",,T$2,"."&$A$43&$L$1&"C"&$A51)="N/A",0,RTD("tos.rtd",,T$2,"."&$A$43&$L$1&"C"&$A51)) -> 690 | U51: =-IF(RTD("tos.rtd",,U$2,"."&$A$43&$L$1&"P"&$A51)="N/A",0,RTD("tos.rtd",,U$2,"."&$A$43&$L$1&"P"&$A51)) -> -536 | V51: =+Hoja2!Y52 -> 4436 | W51: =SUM(P51:V51) -> 8967
A52: =+A51-$A$39 -> 622 | B52: =+IF($A$1="ABS",H52-I52,H52+I52) -> -1032 | C52: =+IF($A$1="ABS",J52-K52,J52+K52) -> 58 | D52: =+IF($A$1="ABS",L52-M52,L52+M52) -> 2335 | E52: =SUM(B52:D52) -> 1361 | F52: =+$F$44/$A$44*A52 -> 25643.142 | H52: =IF(RTD("tos.rtd",,H$43,"."&$A$43&$H$42&"C"&$A52)="N/A",0,RTD("tos.rtd",,H$43,"."&$A$43&$H$42&"C"&$A52)) -> 1459 | I52: =-IF(RTD("tos.rtd",,I$43,"."&$A$43&$H$42&"P"&$A52)="N/A",0,RTD("tos.rtd",,I$43,"."&$A$43&$H$42&"P"&$A52)) -> -2491 | J52: =IF(RTD("tos.rtd",,J$2,"."&$A$43&$J$1&"C"&$A52)="N/A",0,RTD("tos.rtd",,J$2,"."&$A$43&$J$1&"C"&$A52)) -> 1200 | K52: =-IF(RTD("tos.rtd",,K$2,"."&$A$43&$J$1&"P"&$A52)="N/A",0,RTD("tos.rtd",,K$2,"."&$A$43&$J$1&"P"&$A52)) -> -1142 | L52: =IF(RTD("tos.rtd",,L$2,"."&$A$43&$L$1&"C"&$A52)="N/A",0,RTD("tos.rtd",,L$2,"."&$A$43&$L$1&"C"&$A52)) -> 4268 | M52: =-IF(RTD("tos.rtd",,M$2,"."&$A$43&$L$1&"P"&$A52)="N/A",0,RTD("tos.rtd",,M$2,"."&$A$43&$L$1&"P"&$A52)) -> -1933 | N52: =SUM(H52:M52) -> 1361 | O52: =+A52 -> 622 | P52: =IF(RTD("tos.rtd",,P$43,"."&$A$43&$H$42&"C"&$A52)="N/A",0,RTD("tos.rtd",,P$43,"."&$A$43&$H$42&"C"&$A52)) -> 3190 | Q52: =-IF(RTD("tos.rtd",,Q$43,"."&$A$43&$H$42&"P"&$A52)="N/A",0,RTD("tos.rtd",,Q$43,"."&$A$43&$H$42&"P"&$A52)) -> -317 | R52: =IF(RTD("tos.rtd",,R$2,"."&$A$43&$J$1&"C"&$A52)="N/A",0,RTD("tos.rtd",,R$2,"."&$A$43&$J$1&"C"&$A52)) -> 3302 | S52: =-IF(RTD("tos.rtd",,S$2,"."&$A$43&$J$1&"P"&$A52)="N/A",0,RTD("tos.rtd",,S$2,"."&$A$43&$J$1&"P"&$A52)) -> -233 | T52: =IF(RTD("tos.rtd",,T$2,"."&$A$43&$L$1&"C"&$A52)="N/A",0,RTD("tos.rtd",,T$2,"."&$A$43&$L$1&"C"&$A52)) -> 385 | U52: =-IF(RTD("tos.rtd",,U$2,"."&$A$43&$L$1&"P"&$A52)="N/A",0,RTD("tos.rtd",,U$2,"."&$A$43&$L$1&"P"&$A52)) -> -161 | V52: =+Hoja2!Y53 -> 4478 | W52: =SUM(P52:V52) -> 10644
A53: =+A52-$A$39 -> 621 | B53: =+IF($A$1="ABS",H53-I53,H53+I53) -> 202 | C53: =+IF($A$1="ABS",J53-K53,J53+K53) -> 428 | D53: =+IF($A$1="ABS",L53-M53,L53+M53) -> 693 | E53: =SUM(B53:D53) -> 1323 | F53: =+$F$44/$A$44*A53 -> 25601.915 | H53: =IF(RTD("tos.rtd",,H$43,"."&$A$43&$H$42&"C"&$A53)="N/A",0,RTD("tos.rtd",,H$43,"."&$A$43&$H$42&"C"&$A53)) -> 1544 | I53: =-IF(RTD("tos.rtd",,I$43,"."&$A$43&$H$42&"P"&$A53)="N/A",0,RTD("tos.rtd",,I$43,"."&$A$43&$H$42&"P"&$A53)) -> -1342 | J53: =IF(RTD("tos.rtd",,J$2,"."&$A$43&$J$1&"C"&$A53)="N/A",0,RTD("tos.rtd",,J$2,"."&$A$43&$J$1&"C"&$A53)) -> 1017 | K53: =-IF(RTD("tos.rtd",,K$2,"."&$A$43&$J$1&"P"&$A53)="N/A",0,RTD("tos.rtd",,K$2,"."&$A$43&$J$1&"P"&$A53)) -> -589 | L53: =IF(RTD("tos.rtd",,L$2,"."&$A$43&$L$1&"C"&$A53)="N/A",0,RTD("tos.rtd",,L$2,"."&$A$43&$L$1&"C"&$A53)) -> 1712 | M53: =-IF(RTD("tos.rtd",,M$2,"."&$A$43&$L$1&"P"&$A53)="N/A",0,RTD("tos.rtd",,M$2,"."&$A$43&$L$1&"P"&$A53)) -> -1019 | N53: =SUM(H53:M53) -> 1323 | O53: =+A53 -> 621 | P53: =IF(RTD("tos.rtd",,P$43,"."&$A$43&$H$42&"C"&$A53)="N/A",0,RTD("tos.rtd",,P$43,"."&$A$43&$H$42&"C"&$A53)) -> 5012 | Q53: =-IF(RTD("tos.rtd",,Q$43,"."&$A$43&$H$42&"P"&$A53)="N/A",0,RTD("tos.rtd",,Q$43,"."&$A$43&$H$42&"P"&$A53)) -> -392 | R53: =IF(RTD("tos.rtd",,R$2,"."&$A$43&$J$1&"C"&$A53)="N/A",0,RTD("tos.rtd",,R$2,"."&$A$43&$J$1&"C"&$A53)) -> 1413 | S53: =-IF(RTD("tos.rtd",,S$2,"."&$A$43&$J$1&"P"&$A53)="N/A",0,RTD("tos.rtd",,S$2,"."&$A$43&$J$1&"P"&$A53)) -> -98 | T53: =IF(RTD("tos.rtd",,T$2,"."&$A$43&$L$1&"C"&$A53)="N/A",0,RTD("tos.rtd",,T$2,"."&$A$43&$L$1&"C"&$A53)) -> 1145 | U53: =-IF(RTD("tos.rtd",,U$2,"."&$A$43&$L$1&"P"&$A53)="N/A",0,RTD("tos.rtd",,U$2,"."&$A$43&$L$1&"P"&$A53)) -> -104 | V53: =+Hoja2!Y54 -> 6603 | W53: =SUM(P53:V53) -> 13579
A54: =+A53-$A$39 -> 620 | B54: =+IF($A$1="ABS",H54-I54,H54+I54) -> 277 | C54: =+IF($A$1="ABS",J54-K54,J54+K54) -> 673 | D54: =+IF($A$1="ABS",L54-M54,L54+M54) -> 6296 | E54: =SUM(B54:D54) -> 7246 | F54: =+$F$44/$A$44*A54 -> 25560.688 | H54: =IF(RTD("tos.rtd",,H$43,"."&$A$43&$H$42&"C"&$A54)="N/A",0,RTD("tos.rtd",,H$43,"."&$A$43&$H$42&"C"&$A54)) -> 2617 | I54: =-IF(RTD("tos.rtd",,I$43,"."&$A$43&$H$42&"P"&$A54)="N/A",0,RTD("tos.rtd",,I$43,"."&$A$43&$H$42&"P"&$A54)) -> -2340 | J54: =IF(RTD("tos.rtd",,J$2,"."&$A$43&$J$1&"C"&$A54)="N/A",0,RTD("tos.rtd",,J$2,"."&$A$43&$J$1&"C"&$A54)) -> 4581 | K54: =-IF(RTD("tos.rtd",,K$2,"."&$A$43&$J$1&"P"&$A54)="N/A",0,RTD("tos.rtd",,K$2,"."&$A$43&$J$1&"P"&$A54)) -> -3908 | L54: =IF(RTD("tos.rtd",,L$2,"."&$A$43&$L$1&"C"&$A54)="N/A",0,RTD("tos.rtd",,L$2,"."&$A$43&$L$1&"C"&$A54)) -> 16577 | M54: =-IF(RTD("tos.rtd",,M$2,"."&$A$43&$L$1&"P"&$A54)="N/A",0,RTD("tos.rtd",,M$2,"."&$A$43&$L$1&"P"&$A54)) -> -10281 | N54: =SUM(H54:M54) -> 7246 | O54: =+A54 -> 620 | P54: =IF(RTD("tos.rtd",,P$43,"."&$A$43&$H$42&"C"&$A54)="N/A",0,RTD("tos.rtd",,P$43,"."&$A$43&$H$42&"C"&$A54)) -> 12117 | Q54: =-IF(RTD("tos.rtd",,Q$43,"."&$A$43&$H$42&"P"&$A54)="N/A",0,RTD("tos.rtd",,Q$43,"."&$A$43&$H$42&"P"&$A54)) -> -904 | R54: =IF(RTD("tos.rtd",,R$2,"."&$A$43&$J$1&"C"&$A54)="N/A",0,RTD("tos.rtd",,R$2,"."&$A$43&$J$1&"C"&$A54)) -> 14756 | S54: =-IF(RTD("tos.rtd",,S$2,"."&$A$43&$J$1&"P"&$A54)="N/A",0,RTD("tos.rtd",,S$2,"."&$A$43&$J$1&"P"&$A54)) -> -1489 | T54: =IF(RTD("tos.rtd",,T$2,"."&$A$43&$L$1&"C"&$A54)="N/A",0,RTD("tos.rtd",,T$2,"."&$A$43&$L$1&"C"&$A54)) -> 11767 | U54: =-IF(RTD("tos.rtd",,U$2,"."&$A$43&$L$1&"P"&$A54)="N/A",0,RTD("tos.rtd",,U$2,"."&$A$43&$L$1&"P"&$A54)) -> -2026 | V54: =+Hoja2!Y55 -> 23059 | W54: =SUM(P54:V54) -> 57280
A55: =+A54-$A$39 -> 619 | B55: =+IF($A$1="ABS",H55-I55,H55+I55) -> 342 | C55: =+IF($A$1="ABS",J55-K55,J55+K55) -> -3524 | D55: =+IF($A$1="ABS",L55-M55,L55+M55) -> -275 | E55: =SUM(B55:D55) -> -3457 | F55: =+$F$44/$A$44*A55 -> 25519.461 | H55: =IF(RTD("tos.rtd",,H$43,"."&$A$43&$H$42&"C"&$A55)="N/A",0,RTD("tos.rtd",,H$43,"."&$A$43&$H$42&"C"&$A55)) -> 861 | I55: =-IF(RTD("tos.rtd",,I$43,"."&$A$43&$H$42&"P"&$A55)="N/A",0,RTD("tos.rtd",,I$43,"."&$A$43&$H$42&"P"&$A55)) -> -519 | J55: =IF(RTD("tos.rtd",,J$2,"."&$A$43&$J$1&"C"&$A55)="N/A",0,RTD("tos.rtd",,J$2,"."&$A$43&$J$1&"C"&$A55)) -> 775 | K55: =-IF(RTD("tos.rtd",,K$2,"."&$A$43&$J$1&"P"&$A55)="N/A",0,RTD("tos.rtd",,K$2,"."&$A$43&$J$1&"P"&$A55)) -> -4299 | L55: =IF(RTD("tos.rtd",,L$2,"."&$A$43&$L$1&"C"&$A55)="N/A",0,RTD("tos.rtd",,L$2,"."&$A$43&$L$1&"C"&$A55)) -> 901 | M55: =-IF(RTD("tos.rtd",,M$2,"."&$A$43&$L$1&"P"&$A55)="N/A",0,RTD("tos.rtd",,M$2,"."&$A$43&$L$1&"P"&$A55)) -> -1176 | N55: =SUM(H55:M55) -> -3457 | O55: =+A55 -> 619 | P55: =IF(RTD("tos.rtd",,P$43,"."&$A$43&$H$42&"C"&$A55)="N/A",0,RTD("tos.rtd",,P$43,"."&$A$43&$H$42&"C"&$A55)) -> 5020 | Q55: =-IF(RTD("tos.rtd",,Q$43,"."&$A$43&$H$42&"P"&$A55)="N/A",0,RTD("tos.rtd",,Q$43,"."&$A$43&$H$42&"P"&$A55)) -> -390 | R55: =IF(RTD("tos.rtd",,R$2,"."&$A$43&$J$1&"C"&$A55)="N/A",0,RTD("tos.rtd",,R$2,"."&$A$43&$J$1&"C"&$A55)) -> 1447 | S55: =-IF(RTD("tos.rtd",,S$2,"."&$A$43&$J$1&"P"&$A55)="N/A",0,RTD("tos.rtd",,S$2,"."&$A$43&$J$1&"P"&$A55)) -> -388 | T55: =IF(RTD("tos.rtd",,T$2,"."&$A$43&$L$1&"C"&$A55)="N/A",0,RTD("tos.rtd",,T$2,"."&$A$43&$L$1&"C"&$A55)) -> 456 | U55: =-IF(RTD("tos.rtd",,U$2,"."&$A$43&$L$1&"P"&$A55)="N/A",0,RTD("tos.rtd",,U$2,"."&$A$43&$L$1&"P"&$A55)) -> -90 | V55: =+Hoja2!Y56 -> 6698 | W55: =SUM(P55:V55) -> 12753
A56: =+A55-$A$39 -> 618 | B56: =+IF($A$1="ABS",H56-I56,H56+I56) -> 532 | C56: =+IF($A$1="ABS",J56-K56,J56+K56) -> -3937 | D56: =+IF($A$1="ABS",L56-M56,L56+M56) -> -418 | E56: =SUM(B56:D56) -> -3823 | F56: =+$F$44/$A$44*A56 -> 25478.234 | H56: =IF(RTD("tos.rtd",,H$43,"."&$A$43&$H$42&"C"&$A56)="N/A",0,RTD("tos.rtd",,H$43,"."&$A$43&$H$42&"C"&$A56)) -> 2405 | I56: =-IF(RTD("tos.rtd",,I$43,"."&$A$43&$H$42&"P"&$A56)="N/A",0,RTD("tos.rtd",,I$43,"."&$A$43&$H$42&"P"&$A56)) -> -1873 | J56: =IF(RTD("tos.rtd",,J$2,"."&$A$43&$J$1&"C"&$A56)="N/A",0,RTD("tos.rtd",,J$2,"."&$A$43&$J$1&"C"&$A56)) -> 1585 | K56: =-IF(RTD("tos.rtd",,K$2,"."&$A$43&$J$1&"P"&$A56)="N/A",0,RTD("tos.rtd",,K$2,"."&$A$43&$J$1&"P"&$A56)) -> -5522 | L56: =IF(RTD("tos.rtd",,L$2,"."&$A$43&$L$1&"C"&$A56)="N/A",0,RTD("tos.rtd",,L$2,"."&$A$43&$L$1&"C"&$A56)) -> 3741 | M56: =-IF(RTD("tos.rtd",,M$2,"."&$A$43&$L$1&"P"&$A56)="N/A",0,RTD("tos.rtd",,M$2,"."&$A$43&$L$1&"P"&$A56)) -> -4159 | N56: =SUM(H56:M56) -> -3823 | O56: =+A56 -> 618 | P56: =IF(RTD("tos.rtd",,P$43,"."&$A$43&$H$42&"C"&$A56)="N/A",0,RTD("tos.rtd",,P$43,"."&$A$43&$H$42&"C"&$A56)) -> 11416 | Q56: =-IF(RTD("tos.rtd",,Q$43,"."&$A$43&$H$42&"P"&$A56)="N/A",0,RTD("tos.rtd",,Q$43,"."&$A$43&$H$42&"P"&$A56)) -> -1026 | R56: =IF(RTD("tos.rtd",,R$2,"."&$A$43&$J$1&"C"&$A56)="N/A",0,RTD("tos.rtd",,R$2,"."&$A$43&$J$1&"C"&$A56)) -> 2218 | S56: =-IF(RTD("tos.rtd",,S$2,"."&$A$43&$J$1&"P"&$A56)="N/A",0,RTD("tos.rtd",,S$2,"."&$A$43&$J$1&"P"&$A56)) -> -494 | T56: =IF(RTD("tos.rtd",,T$2,"."&$A$43&$L$1&"C"&$A56)="N/A",0,RTD("tos.rtd",,T$2,"."&$A$43&$L$1&"C"&$A56)) -> 831 | U56: =-IF(RTD("tos.rtd",,U$2,"."&$A$43&$L$1&"P"&$A56)="N/A",0,RTD("tos.rtd",,U$2,"."&$A$43&$L$1&"P"&$A56)) -> -2311 | V56: =+Hoja2!Y57 -> 17423 | W56: =SUM(P56:V56) -> 28057
A57: =+A56-$A$39 -> 617 | B57: =+IF($A$1="ABS",H57-I57,H57+I57) -> 797 | C57: =+IF($A$1="ABS",J57-K57,J57+K57) -> -2539 | D57: =+IF($A$1="ABS",L57-M57,L57+M57) -> -4280 | E57: =SUM(B57:D57) -> -6022 | F57: =+$F$44/$A$44*A57 -> 25437.007 | H57: =IF(RTD("tos.rtd",,H$43,"."&$A$43&$H$42&"C"&$A57)="N/A",0,RTD("tos.rtd",,H$43,"."&$A$43&$H$42&"C"&$A57)) -> 2021 | I57: =-IF(RTD("tos.rtd",,I$43,"."&$A$43&$H$42&"P"&$A57)="N/A",0,RTD("tos.rtd",,I$43,"."&$A$43&$H$42&"P"&$A57)) -> -1224 | J57: =IF(RTD("tos.rtd",,J$2,"."&$A$43&$J$1&"C"&$A57)="N/A",0,RTD("tos.rtd",,J$2,"."&$A$43&$J$1&"C"&$A57)) -> 807 | K57: =-IF(RTD("tos.rtd",,K$2,"."&$A$43&$J$1&"P"&$A57)="N/A",0,RTD("tos.rtd",,K$2,"."&$A$43&$J$1&"P"&$A57)) -> -3346 | L57: =IF(RTD("tos.rtd",,L$2,"."&$A$43&$L$1&"C"&$A57)="N/A",0,RTD("tos.rtd",,L$2,"."&$A$43&$L$1&"C"&$A57)) -> 748 | M57: =-IF(RTD("tos.rtd",,M$2,"."&$A$43&$L$1&"P"&$A57)="N/A",0,RTD("tos.rtd",,M$2,"."&$A$43&$L$1&"P"&$A57)) -> -5028 | N57: =SUM(H57:M57) -> -6022 | O57: =+A57 -> 617 | P57: =IF(RTD("tos.rtd",,P$43,"."&$A$43&$H$42&"C"&$A57)="N/A",0,RTD("tos.rtd",,P$43,"."&$A$43&$H$42&"C"&$A57)) -> 7060 | Q57: =-IF(RTD("tos.rtd",,Q$43,"."&$A$43&$H$42&"P"&$A57)="N/A",0,RTD("tos.rtd",,Q$43,"."&$A$43&$H$42&"P"&$A57)) -> -265 | R57: =IF(RTD("tos.rtd",,R$2,"."&$A$43&$J$1&"C"&$A57)="N/A",0,RTD("tos.rtd",,R$2,"."&$A$43&$J$1&"C"&$A57)) -> 1749 | S57: =-IF(RTD("tos.rtd",,S$2,"."&$A$43&$J$1&"P"&$A57)="N/A",0,RTD("tos.rtd",,S$2,"."&$A$43&$J$1&"P"&$A57)) -> -734 | T57: =IF(RTD("tos.rtd",,T$2,"."&$A$43&$L$1&"C"&$A57)="N/A",0,RTD("tos.rtd",,T$2,"."&$A$43&$L$1&"C"&$A57)) -> 349 | U57: =-IF(RTD("tos.rtd",,U$2,"."&$A$43&$L$1&"P"&$A57)="N/A",0,RTD("tos.rtd",,U$2,"."&$A$43&$L$1&"P"&$A57)) -> -4490 | V57: =+Hoja2!Y58 -> 8982 | W57: =SUM(P57:V57) -> 12651
A58: =+A57-$A$39 -> 616 | B58: =+IF($A$1="ABS",H58-I58,H58+I58) -> 223 | C58: =+IF($A$1="ABS",J58-K58,J58+K58) -> -3806 | D58: =+IF($A$1="ABS",L58-M58,L58+M58) -> -1450 | E58: =SUM(B58:D58) -> -5033 | F58: =+$F$44/$A$44*A58 -> 25395.78 | H58: =IF(RTD("tos.rtd",,H$43,"."&$A$43&$H$42&"C"&$A58)="N/A",0,RTD("tos.rtd",,H$43,"."&$A$43&$H$42&"C"&$A58)) -> 1634 | I58: =-IF(RTD("tos.rtd",,I$43,"."&$A$43&$H$42&"P"&$A58)="N/A",0,RTD("tos.rtd",,I$43,"."&$A$43&$H$42&"P"&$A58)) -> -1411 | J58: 1 | K58: =-IF(RTD("tos.rtd",,K$2,"."&$A$43&$J$1&"P"&$A58)="N/A",0,RTD("tos.rtd",,K$2,"."&$A$43&$J$1&"P"&$A58)) -> -3807 | L58: =IF(RTD("tos.rtd",,L$2,"."&$A$43&$L$1&"C"&$A58)="N/A",0,RTD("tos.rtd",,L$2,"."&$A$43&$L$1&"C"&$A58)) -> 1661 | M58: =-IF(RTD("tos.rtd",,M$2,"."&$A$43&$L$1&"P"&$A58)="N/A",0,RTD("tos.rtd",,M$2,"."&$A$43&$L$1&"P"&$A58)) -> -3111 | N58: =SUM(H58:M58) -> -5033 | O58: =+A58 -> 616 | P58: =IF(RTD("tos.rtd",,P$43,"."&$A$43&$H$42&"C"&$A58)="N/A",0,RTD("tos.rtd",,P$43,"."&$A$43&$H$42&"C"&$A58)) -> 6588 | Q58: =-IF(RTD("tos.rtd",,Q$43,"."&$A$43&$H$42&"P"&$A58)="N/A",0,RTD("tos.rtd",,Q$43,"."&$A$43&$H$42&"P"&$A58)) -> -734 | R58: =IF(RTD("tos.rtd",,R$2,"."&$A$43&$J$1&"C"&$A58)="N/A",0,RTD("tos.rtd",,R$2,"."&$A$43&$J$1&"C"&$A58)) -> 1876 | S58: =-IF(RTD("tos.rtd",,S$2,"."&$A$43&$J$1&"P"&$A58)="N/A",0,RTD("tos.rtd",,S$2,"."&$A$43&$J$1&"P"&$A58)) -> -801 | T58: =IF(RTD("tos.rtd",,T$2,"."&$A$43&$L$1&"C"&$A58)="N/A",0,RTD("tos.rtd",,T$2,"."&$A$43&$L$1&"C"&$A58)) -> 336 | U58: =-IF(RTD("tos.rtd",,U$2,"."&$A$43&$L$1&"P"&$A58)="N/A",0,RTD("tos.rtd",,U$2,"."&$A$43&$L$1&"P"&$A58)) -> -129 | V58: =+Hoja2!Y59 -> 9261 | W58: =SUM(P58:V58) -> 16397
A59: =+A58-$A$39 -> 615 | B59: =+IF($A$1="ABS",H59-I59,H59+I59) -> 1356 | C59: =+IF($A$1="ABS",J59-K59,J59+K59) -> -19362 | D59: =+IF($A$1="ABS",L59-M59,L59+M59) -> -18796 | E59: =SUM(B59:D59) -> -36802 | F59: =+$F$44/$A$44*A59 -> 25354.553 | H59: =IF(RTD("tos.rtd",,H$43,"."&$A$43&$H$42&"C"&$A59)="N/A",0,RTD("tos.rtd",,H$43,"."&$A$43&$H$42&"C"&$A59)) -> 3128 | I59: =-IF(RTD("tos.rtd",,I$43,"."&$A$43&$H$42&"P"&$A59)="N/A",0,RTD("tos.rtd",,I$43,"."&$A$43&$H$42&"P"&$A59)) -> -1772 | J59: =IF(RTD("tos.rtd",,J$2,"."&$A$43&$J$1&"C"&$A59)="N/A",0,RTD("tos.rtd",,J$2,"."&$A$43&$J$1&"C"&$A59)) -> 4514 | K59: =-IF(RTD("tos.rtd",,K$2,"."&$A$43&$J$1&"P"&$A59)="N/A",0,RTD("tos.rtd",,K$2,"."&$A$43&$J$1&"P"&$A59)) -> -23876 | L59: =IF(RTD("tos.rtd",,L$2,"."&$A$43&$L$1&"C"&$A59)="N/A",0,RTD("tos.rtd",,L$2,"."&$A$43&$L$1&"C"&$A59)) -> 7846 | M59: =-IF(RTD("tos.rtd",,M$2,"."&$A$43&$L$1&"P"&$A59)="N/A",0,RTD("tos.rtd",,M$2,"."&$A$43&$L$1&"P"&$A59)) -> -26642 | N59: =SUM(H59:M59) -> -36802 | O59: =+A59 -> 615 | P59: =IF(RTD("tos.rtd",,P$43,"."&$A$43&$H$42&"C"&$A59)="N/A",0,RTD("tos.rtd",,P$43,"."&$A$43&$H$42&"C"&$A59)) -> 31315 | Q59: =-IF(RTD("tos.rtd",,Q$43,"."&$A$43&$H$42&"P"&$A59)="N/A",0,RTD("tos.rtd",,Q$43,"."&$A$43&$H$42&"P"&$A59)) -> -1690 | R59: =IF(RTD("tos.rtd",,R$2,"."&$A$43&$J$1&"C"&$A59)="N/A",0,RTD("tos.rtd",,R$2,"."&$A$43&$J$1&"C"&$A59)) -> 13405 | S59: =-IF(RTD("tos.rtd",,S$2,"."&$A$43&$J$1&"P"&$A59)="N/A",0,RTD("tos.rtd",,S$2,"."&$A$43&$J$1&"P"&$A59)) -> -3913 | T59: =IF(RTD("tos.rtd",,T$2,"."&$A$43&$L$1&"C"&$A59)="N/A",0,RTD("tos.rtd",,T$2,"."&$A$43&$L$1&"C"&$A59)) -> 3208 | U59: =-IF(RTD("tos.rtd",,U$2,"."&$A$43&$L$1&"P"&$A59)="N/A",0,RTD("tos.rtd",,U$2,"."&$A$43&$L$1&"P"&$A59)) -> -14440 | V59: =+Hoja2!Y60 -> 50490 | W59: =SUM(P59:V59) -> 78375
A60: =+A59-$A$39 -> 614 | B60: =+IF($A$1="ABS",H60-I60,H60+I60) -> 141 | C60: =+IF($A$1="ABS",J60-K60,J60+K60) -> 438 | D60: =+IF($A$1="ABS",L60-M60,L60+M60) -> 245 | E60: =SUM(B60:D60) -> 824 | F60: =+$F$44/$A$44*A60 -> 25313.327 | H60: =IF(RTD("tos.rtd",,H$43,"."&$A$43&$H$42&"C"&$A60)="N/A",0,RTD("tos.rtd",,H$43,"."&$A$43&$H$42&"C"&$A60)) -> 1437 | I60: =-IF(RTD("tos.rtd",,I$43,"."&$A$43&$H$42&"P"&$A60)="N/A",0,RTD("tos.rtd",,I$43,"."&$A$43&$H$42&"P"&$A60)) -> -1296 | J60: =IF(RTD("tos.rtd",,J$2,"."&$A$43&$J$1&"C"&$A60)="N/A",0,RTD("tos.rtd",,J$2,"."&$A$43&$J$1&"C"&$A60)) -> 1002 | K60: =-IF(RTD("tos.rtd",,K$2,"."&$A$43&$J$1&"P"&$A60)="N/A",0,RTD("tos.rtd",,K$2,"."&$A$43&$J$1&"P"&$A60)) -> -564 | L60: =IF(RTD("tos.rtd",,L$2,"."&$A$43&$L$1&"C"&$A60)="N/A",0,RTD("tos.rtd",,L$2,"."&$A$43&$L$1&"C"&$A60)) -> 1516 | M60: =-IF(RTD("tos.rtd",,M$2,"."&$A$43&$L$1&"P"&$A60)="N/A",0,RTD("tos.rtd",,M$2,"."&$A$43&$L$1&"P"&$A60)) -> -1271 | N60: =SUM(H60:M60) -> 824 | O60: =+A60 -> 614 | P60: =IF(RTD("tos.rtd",,P$43,"."&$A$43&$H$42&"C"&$A60)="N/A",0,RTD("tos.rtd",,P$43,"."&$A$43&$H$42&"C"&$A60)) -> 29389 | Q60: =-IF(RTD("tos.rtd",,Q$43,"."&$A$43&$H$42&"P"&$A60)="N/A",0,RTD("tos.rtd",,Q$43,"."&$A$43&$H$42&"P"&$A60)) -> -1183 | R60: =IF(RTD("tos.rtd",,R$2,"."&$A$43&$J$1&"C"&$A60)="N/A",0,RTD("tos.rtd",,R$2,"."&$A$43&$J$1&"C"&$A60)) -> 1796 | S60: =-IF(RTD("tos.rtd",,S$2,"."&$A$43&$J$1&"P"&$A60)="N/A",0,RTD("tos.rtd",,S$2,"."&$A$43&$J$1&"P"&$A60)) -> -386 | T60: =IF(RTD("tos.rtd",,T$2,"."&$A$43&$L$1&"C"&$A60)="N/A",0,RTD("tos.rtd",,T$2,"."&$A$43&$L$1&"C"&$A60)) -> 320 | U60: =-IF(RTD("tos.rtd",,U$2,"."&$A$43&$L$1&"P"&$A60)="N/A",0,RTD("tos.rtd",,U$2,"."&$A$43&$L$1&"P"&$A60)) -> -288 | V60: =+Hoja2!Y61 -> 30483 | W60: =SUM(P60:V60) -> 60131
A61: =+A60-$A$39 -> 613 | B61: =+IF($A$1="ABS",H61-I61,H61+I61) -> 2140 | C61: =+IF($A$1="ABS",J61-K61,J61+K61) -> 470 | D61: =+IF($A$1="ABS",L61-M61,L61+M61) -> -1792 | E61: =SUM(B61:D61) -> 818 | F61: =+$F$44/$A$44*A61 -> 25272.1 | H61: =IF(RTD("tos.rtd",,H$43,"."&$A$43&$H$42&"C"&$A61)="N/A",0,RTD("tos.rtd",,H$43,"."&$A$43&$H$42&"C"&$A61)) -> 3174 | I61: =-IF(RTD("tos.rtd",,I$43,"."&$A$43&$H$42&"P"&$A61)="N/A",0,RTD("tos.rtd",,I$43,"."&$A$43&$H$42&"P"&$A61)) -> -1034 | J61: =IF(RTD("tos.rtd",,J$2,"."&$A$43&$J$1&"C"&$A61)="N/A",0,RTD("tos.rtd",,J$2,"."&$A$43&$J$1&"C"&$A61)) -> 1950 | K61: =-IF(RTD("tos.rtd",,K$2,"."&$A$43&$J$1&"P"&$A61)="N/A",0,RTD("tos.rtd",,K$2,"."&$A$43&$J$1&"P"&$A61)) -> -1480 | L61: =IF(RTD("tos.rtd",,L$2,"."&$A$43&$L$1&"C"&$A61)="N/A",0,RTD("tos.rtd",,L$2,"."&$A$43&$L$1&"C"&$A61)) -> 637 | M61: =-IF(RTD("tos.rtd",,M$2,"."&$A$43&$L$1&"P"&$A61)="N/A",0,RTD("tos.rtd",,M$2,"."&$A$43&$L$1&"P"&$A61)) -> -2429 | N61: =SUM(H61:M61) -> 818 | O61: =+A61 -> 613 | P61: =IF(RTD("tos.rtd",,P$43,"."&$A$43&$H$42&"C"&$A61)="N/A",0,RTD("tos.rtd",,P$43,"."&$A$43&$H$42&"C"&$A61)) -> 9578 | Q61: =-IF(RTD("tos.rtd",,Q$43,"."&$A$43&$H$42&"P"&$A61)="N/A",0,RTD("tos.rtd",,Q$43,"."&$A$43&$H$42&"P"&$A61)) -> -843 | R61: =IF(RTD("tos.rtd",,R$2,"."&$A$43&$J$1&"C"&$A61)="N/A",0,RTD("tos.rtd",,R$2,"."&$A$43&$J$1&"C"&$A61)) -> 5373 | S61: =-IF(RTD("tos.rtd",,S$2,"."&$A$43&$J$1&"P"&$A61)="N/A",0,RTD("tos.rtd",,S$2,"."&$A$43&$J$1&"P"&$A61)) -> -1743 | T61: =IF(RTD("tos.rtd",,T$2,"."&$A$43&$L$1&"C"&$A61)="N/A",0,RTD("tos.rtd",,T$2,"."&$A$43&$L$1&"C"&$A61)) -> 439 | U61: =-IF(RTD("tos.rtd",,U$2,"."&$A$43&$L$1&"P"&$A61)="N/A",0,RTD("tos.rtd",,U$2,"."&$A$43&$L$1&"P"&$A61)) -> -233 | V61: =+Hoja2!Y62 -> 16084 | W61: =SUM(P61:V61) -> 28655
...

Sheet Hoja2
A1: =TEXT(IF(HOUR(NOW())>=17,NOW()+1,NOW()),"YYMMDD") -> 251109 | B1: =IF(AND(TEXT(B3,"YYMMDD")>$A$1,TEXT(B3,"YYMMDD")<>Hoja1!$C$2,TEXT(B3,"YYMMDD")<>Hoja1!$D$2),TEXT(B3,"YYMMDD"),"") -> 251110 | C1: =IF(AND(TEXT(C3,"YYMMDD")>$A$1,TEXT(C3,"YYMMDD")<>Hoja1!$C$2,TEXT(C3,"YYMMDD")<>Hoja1!$D$2),TEXT(C3,"YYMMDD"),"") -> 251111 | D1: =IF(AND(TEXT(D3,"YYMMDD")>$A$1,TEXT(D3,"YYMMDD")<>Hoja1!$C$2,TEXT(D3,"YYMMDD")<>Hoja1!$D$2),TEXT(D3,"YYMMDD"),"") -> 251112 | E1: =IF(AND(TEXT(E3,"YYMMDD")>$A$1,TEXT(E3,"YYMMDD")<>Hoja1!$C$2,TEXT(E3,"YYMMDD")<>Hoja1!$D$2),TEXT(E3,"YYMMDD"),"") -> 251113 | F1: =IF(AND(TEXT(F3,"YYMMDD")>$A$1,TEXT(F3,"YYMMDD")<>Hoja1!$C$2,TEXT(F3,"YYMMDD")<>Hoja1!$D$2),TEXT(F3,"YYMMDD"),"") | G1: =IF(AND(TEXT(G3,"YYMMDD")>$A$1,TEXT(G3,"YYMMDD")<>Hoja1!$C$2,TEXT(G3,"YYMMDD")<>Hoja1!$D$2),TEXT(G3,"YYMMDD"),"") | H1: =IF(AND(TEXT(H3,"YYMMDD")>$A$1,TEXT(H3,"YYMMDD")<>Hoja1!$C$2,TEXT(H3,"YYMMDD")<>Hoja1!$D$2),TEXT(H3,"YYMMDD"),"") -> 251128 | I1: =IF(AND(TEXT(I3,"YYMMDD")>$A$1,TEXT(I3,"YYMMDD")<>Hoja1!$C$2,TEXT(I3,"YYMMDD")<>Hoja1!$D$2),TEXT(I3,"YYMMDD"),"") -> 251205 | ... X1: =IF(AND(TEXT(X3,"YYMMDD")>$A$1,TEXT(X3,"YYMMDD")<>Hoja1!$C$2,TEXT(X3,"YYMMDD")<>Hoja1!$D$2),TEXT(X3,"YYMMDD"),"") -> 261030
A2: VOLUME | B2: =+A3 -> SPY | C2: =+B2 -> SPY | D2: =+C2 -> SPY | E2: =+D2 -> SPY | F2: =+E2 -> SPY | G2: =+F2 -> SPY | H2: =+G2 -> SPY | I2: =+H2 -> SPY | J2: =+I2 -> SPY | ... L2: =+K2 -> SPY | M2: =+K2 -> SPY | N2: =+L2 -> SPY | O2: =+M2 -> SPY | P2: =+N2 -> SPY | Q2: =+O2 -> SPY | R2: =+P2 -> SPY | S2: =+Q2 -> SPY | T2: =+R2 -> SPY | ... X2: =+V2 -> SPY
A3: =+Hoja1!A2 -> SPY | B3: 45971 | C3: =+B3+1 -> 45972 | D3: =+C3+1 -> 45973 | E3: =+D3+1 -> 45974 | F3: =+E3+1 -> 45975 | G3: =+F3+7 -> 45982 | H3: =+G3+7 -> 45989 | I3: =+H3+7 -> 45996 | J3: =+I3+7 -> 46003 | K3: =+J3+7 -> 46010 | L3: =+J3+7+7+7+7 -> 46031 | M3: =+L3+7+7+7 -> 46052 | N3: =+M3+7 -> 46059 | O3: 46022 | P3: =+N3+7+7+7 -> 46080 | Q3: =+P3+7+7+7+7+7 -> 46115 | R3: =+Q3+7+7+7+7 -> 46143 | S3: =+R3+7+7+7+7 -> 46171 | T3: =+S3+7+7+7+7 -> 46199 | U3: =+T3+7+7+7+7+7 -> 46234 | V3: =+U3+7+7+7+7 -> 46262 | W3: =+V3+7+7+7+7+7 -> 46297 | X3: =+W3+7+7+7+7 -> 46325
A4: =+Hoja1!A3 -> 672.36
