Workbook

Sheet OI-VOL (2)
A1: 0.5 | B1: =IF($A$52<=TEXT(B3,"YYMMDD"),TEXT(B3,"YYMMDD"),"") | C1: =IF($A$52<=TEXT(C3,"YYMMDD"),TEXT(C3,"YYMMDD"),"") -> 251114 | D1: =IF($A$52<=TEXT(D3,"YYMMDD"),TEXT(D3,"YYMMDD"),"") -> 251121 | E1: =IF($A$52<=TEXT(E3,"YYMMDD"),TEXT(E3,"YYMMDD"),"") -> 251128 | F1: =IF($A$52<=TEXT(F3,"YYMMDD"),TEXT(F3,"YYMMDD"),"") -> 251205 | G1: =IF($A$52<=TEXT(G3,"YYMMDD"),TEXT(G3,"YYMMDD"),"") -> 251212 | H1: =IF($A$52<=TEXT(H3,"YYMMDD"),TEXT(H3,"YYMMDD"),"") -> 251219 | I1: =IF($A$52<=TEXT(I3,"YYMMDD"),TEXT(I3,"YYMMDD"),"") -> 251226 | ... W1: =IF($A$52<=TEXT(W3,"YYMMDD"),TEXT(W3,"YYMMDD"),"") -> 261218
A2: VOLUME | B2: =+A3 -> OPEN | C2: =+B2 -> OPEN | D2: =+C2 -> OPEN | E2: =+D2 -> OPEN | F2: =+E2 -> OPEN | G2: =+F2 -> OPEN | H2: =+G2 -> OPEN | I2: =+H2 -> OPEN | J2: =+I2 -> OPEN | ... W2: =+V2 -> OPEN | Y2: =+A2 -> VOLUME | Z2: =+'OI-VOL'!A2 -> OPEN_INT | AB2: =INDEX(A5:A51,MATCH(MIN(AB5:AB51),AB5:AB51,0)) -> 7
A3: OPEN | B3: 45968 | C3: =+B3+7 -> 45975 | D3: =+C3+7 -> 45982 | E3: =+D3+7 -> 45989 | F3: =+E3+7 -> 45996 | G3: =+F3+7 -> 46003 | H3: =+G3+7 -> 46010 | I3: =+H3+7 -> 46017 | J3: =+I3+7 -> 46024 | ... L3: =+K3+7 -> 46038 | M3: =+L3+7+7+7+7+7 -> 46073 | N3: =+M3+7+7+7+7 -> 46101 | O3: =+N3+7+7+7+7 -> 46129 | P3: =+O3+7+7+7+7 -> 46157 | Q3: =+P3+7+7+7+7+7 -> 46192 | R3: =+Q3+7+7+7+7 -> 46220 | S3: =+R3+7+7+7+7+7 -> 46255 | T3: =+S3+7+7+7+7 -> 46283 | U3: =+T3+7+7+7+7 -> 46311 | V3: =+U3+7+7+7+7+7 -> 46346 | W3: =+V3+7+7+7+7 -> 46374 | AB3: =+A3 -> OPEN
A4: =RTD("tos.rtd",,"MARK",A3) -> 8.01 | B4: =SUM(B5:B51) -> 0 | C4: =SUM(C5:C51) -> 0 | D4: =SUM(D5:D51) -> 0 | E4: =SUM(E5:E51) -> 0 | F4: =SUM(F5:F51) -> 0 | G4: =SUM(G5:G51) -> 0 | H4: =SUM(H5:H51) -> 0 | I4: =SUM(I5:I51) -> 0 | ... W4: =SUM(W5:W51) -> 0 | Y4: =INDEX(A5:A51,MATCH(MAX(Y5:Y51),Y5:Y51,0)) -> 21.5 | AB4: 251114 | AC4: =+A6+$A$1 -> 21.5 | AD4: =+AC4-$A$1 -> 21 | AE4: =+AD4-$A$1 -> 20.5 | AF4: =+AE4-$A$1 -> 20 | AG4: =+AF4-$A$1 -> 19.5 | AH4: =+AG4-$A$1 -> 19 | AI4: =+AH4-$A$1 -> 18.5 | AJ4: =+AI4-$A$1 -> 18 | AK4: =+AJ4-$A$1 -> 17.5 | ... BW4: =+BV4-$A$1 -> -1.5
A5: =+A6+$A$1 -> 21.5 | B5: =IF($A$2="PREMIUM_OI",IFERROR(IF($X$1="ABS",(100*RTD("tos.rtd",,"OPEN_INT","."&B$2&B$1&"C"&$A5)*RTD("tos.rtd",,"LAST","."&B$2&B$1&"C"&$A5)+100*RTD("tos.rtd",,"OPEN_INT","."&B$2&B$1&"P"&$A5)*RTD("tos.rtd",,"LAST","."&B$2&B$1&"P"&$A5))/1000000,(100*RTD("tos.rtd",,"OPEN_INT","."&B$2&B$1&"C"&$A5)*RTD("tos.rtd",,"LAST","."&B$2&B$1&"C"&$A5)-100*RTD("tos.rtd",,"OPEN_INT","."&B$2&B$1&"P"&$A5)*RTD("tos.rtd",,"LAST","."&B$2&B$1&"P"&$A5))/1000000),0),IF($A$2="PREMIUM",IFERROR(IF($X$1="ABS",(100*RTD("tos.rtd",,"VOLUME","."&B$2&B$1&"C"&$A5)*RTD("tos.rtd",,"LAST","."&B$2&B$1&"C"&$A5)+100*RTD("tos.rtd",,"VOLUME","."&B$2&B$1&"P"&$A5)*RTD("tos.rtd",,"LAST","."&B$2&B$1&"P"&$A5))/1000000,(100*RTD("tos.rtd",,"VOLUME","."&B$2&B$1&"C"&$A5)*RTD("tos.rtd",,"LAST","."&B$2&B$1&"C"&$A5)-100*RTD("tos.rtd",,"VOLUME","."&B$2&B$1&"P"&$A5)*RTD("tos.rtd",,"LAST","."&B$2&B$1&"P"&$A5))/1000000),0),IF($A$2="DEX",IFERROR(IF($X$1="ABS",(100*RTD("tos.rtd",,"OPEN_INT","."&B$2&B$1&"C"&$A5)*RTD("tos.rtd",,"DELTA","."&B$2&B$1&"C"&$A5)+100*RTD("tos.rtd",,"OPEN_INT","."&B$2&B$1&"P"&$A5)*RTD("tos.rtd",,"DELTA","."&B$2&B$1&"P"&$A5))/1000,(100*RTD("tos.rtd",,"OPEN_INT","."&B$2&B$1&"C"&$A5)*RTD("tos.rtd",,"DELTA","."&B$2&B$1&"C"&$A5)-100*RTD("tos.rtd",,"OPEN_INT","."&B$2&B$1&"P"&$A5)*RTD("tos.rtd",,"DELTA","."&B$2&B$1&"P"&$A5))/1000),0),IF($A$2="VEX",IFERROR(IF($X$1="ABS",($A$4*$A$4*RTD("tos.rtd",,"VOLUME","."&B$2&B$1&"C"&$A5)*RTD("tos.rtd",,"GAMMA","."&B$2&B$1&"C"&$A5)+$A$4*$A$4*RTD("tos.rtd",,"VOLUME","."&B$2&B$1&"P"&$A5)*RTD("tos.rtd",,"GAMMA","."&B$2&B$1&"P"&$A5))/1000000,($A$4*$A$4*RTD("tos.rtd",,"VOLUME","."&B$2&B$1&"C"&$A5)*RTD("tos.rtd",,"GAMMA","."&B$2&B$1&"C"&$A5)-$A$4*$A$4*RTD("tos.rtd",,"VOLUME","."&B$2&B$1&"P"&$A5)*RTD("tos.rtd",,"GAMMA","."&B$2&B$1&"P"&$A5))/1000000),0),IF($A$2="GEX",IFERROR(IF($X$1="ABS",($A$4*$A$4*RTD("tos.rtd",,"OPEN_INT","."&B$2&B$1&"C"&$A5)*RTD("tos.rtd",,"GAMMA","."&B$2&B$1&"C"&$A5)+$A$4*$A$4*RTD("tos.rtd",,"OPEN_INT","."&B$2&B$1&"P"&$A5)*RTD("tos.rtd",,"GAMMA","."&B$2&B$1&"P"&$A5))/1000000,($A$4*$A$4*RTD("tos.rtd",,"OPEN_INT","."&B$2&B$1&"C"&$A5)*RTD("tos.rtd",,"GAMMA","."&B$2&B$1&"C"&$A5)-$A$4*$A$4*RTD("tos.rtd",,"OPEN_INT","."&B$2&B$1&"P"&$A5)*RTD("tos.rtd",,"GAMMA","."&B$2&B$1&"P"&$A5))/1000000),0),IF($A$2="SKEW",IFERROR(VALUE(IF(RTD("tos.rtd",,"IMPL_VOL","."&B$2&B$1&"P"&$A5)="N/A",0,RTD("tos.rtd",,"IMPL_VOL","."&B$2&B$1&"P"&$A5))),0)-IFERROR(VALUE(IF(RTD("tos.rtd",,"IMPL_VOL","."&B$2&B$1&"C"&$A5)="N/A",0,RTD("tos.rtd",,"IMPL_VOL","."&B$2&B$1&"C"&$A5))),0),IF($A$2="MAXPAIN",IF($A$4>$A5,($A$4-$A5)*IF(RTD("tos.rtd",,"OPEN_INT","."&B$2&B$1&"C"&$A5)="N/A",0,RTD("tos.rtd",,"OPEN_INT","."&B$2&B$1&"C"&$A5)),0)+IF($A$4<$A5,($A$5-$A$4)*IF(RTD("tos.rtd",,"OPEN_INT","."&B$2&B$1&"P"&$A5)="N/A",0,RTD("tos.rtd",,"OPEN_INT","."&B$2&B$1&"P"&$A5)),0),IF($X$1="ABS",IF(RTD("tos.rtd",,$A$2,"."&B$2&B$1&"C"&$A5)="N/A",0,RTD("tos.rtd",,$A$2,"."&B$2&B$1&"C"&$A5))+IF(RTD("tos.rtd",,$A$2,"."&B$2&B$1&"P"&$A5)="N/A",0,RTD("tos.rtd",,$A$2,"."&B$2&B$1&"P"&$A5)),IF(RTD("tos.rtd",,$A$2,"."&B$2&B$1&"C"&$A5)="N/A",0,RTD("tos.rtd",,$A$2,"."&B$2&B$1&"C"&$A5))-IF(RTD("tos.rtd",,$A$2,"."&B$2&B$1&"P"&$A5)="N/A",0,RTD("tos.rtd",,$A$2,"."&B$2&B$1&"P"&$A5)))))))))) -> 0 | C5: =IF($A$2="PREMIUM_OI",IFERROR(IF($X$1="ABS",(100*RTD("tos.rtd",,"OPEN_INT","."&C$2&C$1&"C"&$A5)*RTD("tos.rtd",,"LAST","."&C$2&C$1&"C"&$A5)+100*RTD("tos.rtd",,"OPEN_INT","."&C$2&C$1&"P"&$A5)*RTD("tos.rtd",,"LAST","."&C$2&C$1&"P"&$A5))/1000000,(100*RTD("tos.rtd",,"OPEN_INT","."&C$2&C$1&"C"&$A5)*RTD("tos.rtd",,"LAST","."&C$2&C$1&"C"&$A5)-100*RTD("tos.rtd",,"OPEN_INT","."&C$2&C$1&"P"&$A5)*RTD("tos.rtd",,"LAST","."&C$2&C$1&"P"&$A5))/1000000),0),IF($A$2="PREMIUM",IFERROR(IF($X$1="ABS",(100*RTD("tos.rtd",,"VOLUME","."&C$2&C$1&"C"&$A5)*RTD("tos.rtd",,"LAST","."&C$2&C$1&"C"&$A5)+100*RTD("tos.rtd",,"VOLUME","."&C$2&C$1&"P"&$A5)*RTD("tos.rtd",,"LAST","."&C$2&C$1&"P"&$A5))/1000000,(100*RTD("tos.rtd",,"VOLUME","."&C$2&C$1&"C"&$A5)*RTD("tos.rtd",,"LAST","."&C$2&C$1&"C"&$A5)-100*RTD("tos.rtd",,"VOLUME","."&C$2&C$1&"P"&$A5)*RTD("tos.rtd",,"LAST","."&C$2&C$1&"P"&$A5))/1000000),0),IF($A$2="DEX",IFERROR(IF($X$1="ABS",(100*RTD("tos.rtd",,"OPEN_INT","."&C$2&C$1&"C"&$A5)*RTD("tos.rtd",,"DELTA","."&C$2&C$1&"C"&$A5)+100*RTD("tos.rtd",,"OPEN_INT","."&C$2&C$1&"P"&$A5)*RTD("tos.rtd",,"DELTA","."&C$2&C$1&"P"&$A5))/1000,(100*RTD("tos.rtd",,"OPEN_INT","."&C$2&C$1&"C"&$A5)*RTD("tos.rtd",,"DELTA","."&C$2&C$1&"C"&$A5)-100*RTD("tos.rtd",,"OPEN_INT","."&C$2&C$1&"P"&$A5)*RTD("tos.rtd",,"DELTA","."&C$2&C$1&"P"&$A5))/1000),0),IF($A$2="VEX",IFERROR(IF($X$1="ABS",($A$4*$A$4*RTD("tos.rtd",,"VOLUME","."&C$2&C$1&"C"&$A5)*RTD("tos.rtd",,"GAMMA","."&C$2&C$1&"C"&$A5)+$A$4*$A$4*RTD("tos.rtd",,"VOLUME","."&C$2&C$1&"P"&$A5)*RTD("tos.rtd",,"GAMMA","."&C$2&C$1&"P"&$A5))/1000000,($A$4*$A$4*RTD("tos.rtd",,"VOLUME","."&C$2&C$1&"C"&$A5)*RTD("tos.rtd",,"GAMMA","."&C$2&C$1&"C"&$A5)-$A$4*$A$4*RTD("tos.rtd",,"VOLUME","."&C$2&C$1&"P"&$A5)*RTD("tos.rtd",,"GAMMA","."&C$2&C$1&"P"&$A5))/1000000),0),IF($A$2="GEX",IFERROR(IF($X$1="ABS",($A$4*$A$4*RTD("tos.rtd",,"OPEN_INT","."&C$2&C$1&"C"&$A5)*RTD("tos.rtd",,"GAMMA","."&C$2&C$1&"C"&$A5)+$A$4*$A$4*RTD("tos.rtd",,"OPEN_INT","."&C$2&C$1&"P"&$A5)*RTD("tos.rtd",,"GAMMA","."&C$2&C$1&"P"&$A5))/1000000,($A$4*$A$4*RTD("tos.rtd",,"OPEN_INT","."&C$2&C$1&"C"&$A5)*RTD("tos.rtd",,"GAMMA","."&C$2&C$1&"C"&$A5)-$A$4*$A$4*RTD("tos.rtd",,"OPEN_INT","."&C$2&C$1&"P"&$A5)*RTD("tos.rtd",,"GAMMA","."&C$2&C$1&"P"&$A5))/1000000),0),IF($A$2="SKEW",IFERROR(VALUE(IF(RTD("tos.rtd",,"IMPL_VOL","."&C$2&C$1&"P"&$A5)="N/A",0,RTD("tos.rtd",,"IMPL_VOL","."&C$2&C$1&"P"&$A5))),0)-IFERROR(VALUE(IF(RTD("tos.rtd",,"IMPL_VOL","."&C$2&C$1&"C"&$A5)="N/A",0,RTD("tos.rtd",,"IMPL_VOL","."&C$2&C$1&"C"&$A5))),0),IF($A$2="MAXPAIN",IF($A$4>$A5,($A$4-$A5)*IF(RTD("tos.rtd",,"OPEN_INT","."&C$2&C$1&"C"&$A5)="N/A",0,RTD("tos.rtd",,"OPEN_INT","."&C$2&C$1&"C"&$A5)),0)+IF($A$4<$A5,($A$5-$A$4)*IF(RTD("tos.rtd",,"OPEN_INT","."&C$2&C$1&"P"&$A5)="N/A",0,RTD("tos.rtd",,"OPEN_INT","."&C$2&C$1&"P"&$A5)),0),IF($X$1="ABS",IF(RTD("tos.rtd",,$A$2,"."&C$2&C$1&"C"&$A5)="N/A",0,RTD("tos.rtd",,$A$2,"."&C$2&C$1&"C"&$A5))+IF(RTD("tos.rtd",,$A$2,"."&C$2&C$1&"P"&$A5)="N/A",0,RTD("tos.rtd",,$A$2,"."&C$2&C$1&"P"&$A5)),IF(RTD("tos.rtd",,$A$2,"."&C$2&C$1&"C"&$A5)="N/A",0,RTD("tos.rtd",,$A$2,"."&C$2&C$1&"C"&$A5))-IF(RTD("tos.rtd",,$A$2,"."&C$2&C$1&"P"&$A5)="N/A",0,RTD("tos.rtd",,$A$2,"."&C$2&C$1&"P"&$A5)))))))))) -> 0 | D5: =IF($A$2="PREMIUM_OI",IFERROR(IF($X$1="ABS",(100*RTD("tos.rtd",,"OPEN_INT","."&D$2&D$1&"C"&$A5)*RTD("tos.rtd",,"LAST","."&D$2&D$1&"C"&$A5)+100*RTD("tos.rtd",,"OPEN_INT","."&D$2&D$1&"P"&$A5)*RTD("tos.rtd",,"LAST","."&D$2&D$1&"P"&$A5))/1000000,(100*RTD("tos.rtd",,"OPEN_INT","."&D$2&D$1&"C"&$A5)*RTD("tos.rtd",,"LAST","."&D$2&D$1&"C"&$A5)-100*RTD("tos.rtd",,"OPEN_INT","."&D$2&D$1&"P"&$A5)*RTD("tos.rtd",,"LAST","."&D$2&D$1&"P"&$A5))/1000000),0),IF($A$2="PREMIUM",IFERROR(IF($X$1="ABS",(100*RTD("tos.rtd",,"VOLUME","."&D$2&D$1&"C"&$A5)*RTD("tos.rtd",,"LAST","."&D$2&D$1&"C"&$A5)+100*RTD("tos.rtd",,"VOLUME","."&D$2&D$1&"P"&$A5)*RTD("tos.rtd",,"LAST","."&D$2&D$1&"P"&$A5))/1000000,(100*RTD("tos.rtd",,"VOLUME","."&D$2&D$1&"C"&$A5)*RTD("tos.rtd",,"LAST","."&D$2&D$1&"C"&$A5)-100*RTD("tos.rtd",,"VOLUME","."&D$2&D$1&"P"&$A5)*RTD("tos.rtd",,"LAST","."&D$2&D$1&"P"&$A5))/1000000),0),IF($A$2="DEX",IFERROR(IF($X$1="ABS",(100*RTD("tos.rtd",,"OPEN_INT","."&D$2&D$1&"C"&$A5)*RTD("tos.rtd",,"DELTA","."&D$2&D$1&"C"&$A5)+100*RTD("tos.rtd",,"OPEN_INT","."&D$2&D$1&"P"&$A5)*RTD("tos.rtd",,"DELTA","."&D$2&D$1&"P"&$A5))/1000,(100*RTD("tos.rtd",,"OPEN_INT","."&D$2&D$1&"C"&$A5)*RTD("tos.rtd",,"DELTA","."&D$2&D$1&"C"&$A5)-100*RTD("tos.rtd",,"OPEN_INT","."&D$2&D$1&"P"&$A5)*RTD("tos.rtd",,"DELTA","."&D$2&D$1&"P"&$A5))/1000),0),IF($A$2="VEX",IFERROR(IF($X$1="ABS",($A$4*$A$4*RTD("tos.rtd",,"VOLUME","."&D$2&D$1&"C"&$A5)*RTD("tos.rtd",,"GAMMA","."&D$2&D$1&"C"&$A5)+$A$4*$A$4*RTD("tos.rtd",,"VOLUME","."&D$2&D$1&"P"&$A5)*RTD("tos.rtd",,"GAMMA","."&D$2&D$1&"P"&$A5))/1000000,($A$4*$A$4*RTD("tos.rtd",,"VOLUME","."&D$2&D$1&"C"&$A5)*RTD("tos.rtd",,"GAMMA","."&D$2&D$1&"C"&$A5)-$A$4*$A$4*RTD("tos.rtd",,"VOLUME","."&D$2&D$1&"P"&$A5)*RTD("tos.rtd",,"GAMMA","."&D$2&D$1&"P"&$A5))/1000000),0),IF($A$2="GEX",IFERROR(IF($X$1="ABS",($A$4*$A$4*RTD("tos.rtd",,"OPEN_INT","."&D$2&D$1&"C"&$A5)*RTD("tos.rtd",,"GAMMA","."&D$2&D$1&"C"&$A5)+$A$4*$A$4*RTD("tos.rtd",,"OPEN_INT","."&D$2&D$1&"P"&$A5)*RTD("tos.rtd",,"GAMMA","."&D$2&D$1&"P"&$A5))/1000000,($A$4*$A$4*RTD("tos.rtd",,"OPEN_INT","."&D$2&D$1&"C"&$A5)*RTD("tos.rtd",,"GAMMA","."&D$2&D$1&"C"&$A5)-$A$4*$A$4*RTD("tos.rtd",,"OPEN_INT","."&D$2&D$1&"P"&$A5)*RTD("tos.rtd",,"GAMMA","."&D$2&D$1&"P"&$A5))/1000000),0),IF($A$2="SKEW",IFERROR(VALUE(IF(RTD("tos.rtd",,"IMPL_VOL","."&D$2&D$1&"P"&$A5)="N/A",0,RTD("tos.rtd",,"IMPL_VOL","."&D$2&D$1&"P"&$A5))),0)-IFERROR(VALUE(IF(RTD("tos.rtd",,"IMPL_VOL","."&D$2&D$1&"C"&$A5)="N/A",0,RTD("tos.rtd",,"IMPL_VOL","."&D$2&D$1&"C"&$A5))),0),IF($A$2="MAXPAIN",IF($A$4>$A5,($A$4-$A5)*IF(RTD("tos.rtd",,"OPEN_INT","."&D$2&D$1&"C"&$A5)="N/A",0,RTD("tos.rtd",,"OPEN_INT","."&D$2&D$1&"C"&$A5)),0)+IF($A$4<$A5,($A$5-$A$4)*IF(RTD("tos.rtd",,"OPEN_INT","."&D$2&D$1&"P"&$A5)="N/A",0,RTD("tos.rtd",,"OPEN_INT","."&D$2&D$1&"P"&$A5)),0),IF($X$1="ABS",IF(RTD("tos.rtd",,$A$2,"."&D$2&D$1&"C"&$A5)="N/A",0,RTD("tos.rtd",,$A$2,"."&D$2&D$1&"C"&$A5))+IF(RTD("tos.rtd",,$A$2,"."&D$2&D$1&"P"&$A5)="N/A",0,RTD("tos.rtd",,$A$2,"."&D$2&D$1&"P"&$A5)),IF(RTD("tos.rtd",,$A$2,"."&D$2&D$1&"C"&$A5)="N/A",0,RTD("tos.rtd",,$A$2,"."&D$2&D$1&"C"&$A5))-IF(RTD("tos.rtd",,$A$2,"."&D$2&D$1&"P"&$A5)="N/A",0,RTD("tos.rtd",,$A$2,"."&D$2&D$1&"P"&$A5)))))))))) -> 0 | E5: =IF($A$2="PREMIUM_OI",IFERROR(IF($X$1="ABS",(100*RTD("tos.rtd",,"OPEN_INT","."&E$2&E$1&"C"&$A5)*RTD("tos.rtd",,"LAST","."&E$2&E$1&"C"&$A5)+100*RTD("tos.rtd",,"OPEN_INT","."&E$2&E$1&"P"&$A5)*RTD("tos.rtd",,"LAST","."&E$2&E$1&"P"&$A5))/1000000,(100*RTD("tos.rtd",,"OPEN_INT","."&E$2&E$1&"C"&$A5)*RTD("tos.rtd",,"LAST","."&E$2&E$1&"C"&$A5)-100*RTD("tos.rtd",,"OPEN_INT","."&E$2&E$1&"P"&$A5)*RTD("tos.rtd",,"LAST","."&E$2&E$1&"P"&$A5))/1000000),0),IF($A$2="PREMIUM",IFERROR(IF($X$1="ABS",(100*RTD("tos.rtd",,"VOLUME","."&E$2&E$1&"C"&$A5)*RTD("tos.rtd",,"LAST","."&E$2&E$1&"C"&$A5)+100*RTD("tos.rtd",,"VOLUME","."&E$2&E$1&"P"&$A5)*RTD("tos.rtd",,"LAST","."&E$2&E$1&"P"&$A5))/1000000,(100*RTD("tos.rtd",,"VOLUME","."&E$2&E$1&"C"&$A5)*RTD("tos.rtd",,"LAST","."&E$2&E$1&"C"&$A5)-100*RTD("tos.rtd",,"VOLUME","."&E$2&E$1&"P"&$A5)*RTD("tos.rtd",,"LAST","."&E$2&E$1&"P"&$A5))/1000000),0),IF($A$2="DEX",IFERROR(IF($X$1="ABS",(100*RTD("tos.rtd",,"OPEN_INT","."&E$2&E$1&"C"&$A5)*RTD("tos.rtd",,"DELTA","."&E$2&E$1&"C"&$A5)+100*RTD("tos.rtd",,"OPEN_INT","."&E$2&E$1&"P"&$A5)*RTD("tos.rtd",,"DELTA","."&E$2&E$1&"P"&$A5))/1000,(100*RTD("tos.rtd",,"OPEN_INT","."&E$2&E$1&"C"&$A5)*RTD("tos.rtd",,"DELTA","."&E$2&E$1&"C"&$A5)-100*RTD("tos.rtd",,"OPEN_INT","."&E$2&E$1&"P"&$A5)*RTD("tos.rtd",,"DELTA","."&E$2&E$1&"P"&$A5))/1000),0),IF($A$2="VEX",IFERROR(IF($X$1="ABS",($A$4*$A$4*RTD("tos.rtd",,"VOLUME","."&E$2&E$1&"C"&$A5)*RTD("tos.rtd",,"GAMMA","."&E$2&E$1&"C"&$A5)+$A$4*$A$4*RTD("tos.rtd",,"VOLUME","."&E$2&E$1&"P"&$A5)*RTD("tos.rtd",,"GAMMA","."&E$2&E$1&"P"&$A5))/1000000,($A$4*$A$4*RTD("tos.rtd",,"VOLUME","."&E$2&E$1&"C"&$A5)*RTD("tos.rtd",,"GAMMA","."&E$2&E$1&"C"&$A5)-$A$4*$A$4*RTD("tos.rtd",,"VOLUME","."&E$2&E$1&"P"&$A5)*RTD("tos.rtd",,"GAMMA","."&E$2&E$1&"P"&$A5))/1000000),0),IF($A$2="GEX",IFERROR(IF($X$1="ABS",($A$4*$A$4*RTD("tos.rtd",,"OPEN_INT","."&E$2&E$1&"C"&$A5)*RTD("tos.rtd",,"GAMMA","."&E$2&E$1&"C"&$A5)+$A$4*$A$4*RTD("tos.rtd",,"OPEN_INT","."&E$2&E$1&"P"&$A5)*RTD("tos.rtd",,"GAMMA","."&E$2&E$1&"P"&$A5))/1000000,($A$4*$A$4*RTD("tos.rtd",,"OPEN_INT","."&E$2&E$1&"C"&$A5)*RTD("tos.rtd",,"GAMMA","."&E$2&E$1&"C"&$A5)-$A$4*$A$4*RTD("tos.rtd",,"OPEN_INT","."&E$2&E$1&"P"&$A5)*RTD("tos.rtd",,"GAMMA","."&E$2&E$1&"P"&$A5))/1000000),0),IF($A$2="SKEW",IFERROR(VALUE(IF(RTD("tos.rtd",,"IMPL_VOL","."&E$2&E$1&"P"&$A5)="N/A",0,RTD("tos.rtd",,"IMPL_VOL","."&E$2&E$1&"P"&$A5))),0)-IFERROR(VALUE(IF(RTD("tos.rtd",,"IMPL_VOL","."&E$2&E$1&"C"&$A5)="N/A",0,RTD("tos.rtd",,"IMPL_VOL","."&E$2&E$1&"C"&$A5))),0),IF($A$2="MAXPAIN",IF($A$4>$A5,($A$4-$A5)*IF(RTD("tos.rtd",,"OPEN_INT","."&E$2&E$1&"C"&$A5)="N/A",0,RTD("tos.rtd",,"OPEN_INT","."&E$2&E$1&"C"&$A5)),0)+IF($A$4<$A5,($A$5-$A$4)*IF(RTD("tos.rtd",,"OPEN_INT","."&E$2&E$1&"P"&$A5)="N/A",0,RTD("tos.rtd",,"OPEN_INT","."&E$2&E$1&"P"&$A5)),0),IF($X$1="ABS",IF(RTD("tos.rtd",,$A$2,"."&E$2&E$1&"C"&$A5)="N/A",0,RTD("tos.rtd",,$A$2,"."&E$2&E$1&"C"&$A5))+IF(RTD("tos.rtd",,$A$2,"."&E$2&E$1&"P"&$A5)="N/A",0,RTD("tos.rtd",,$A$2,"."&E$2&E$1&"P"&$A5)),IF(RTD("tos.rtd",,$A$2,"."&E$2&E$1&"C"&$A5)="N/A",0,RTD("tos.rtd",,$A$2,"."&E$2&E$1&"C"&$A5))-IF(RTD("tos.rtd",,$A$2,"."&E$2&E$1&"P"&$A5)="N/A",0,RTD("tos.rtd",,$A$2,"."&E$2&E$1&"P"&$A5)))))))))) -> 0 | F5: =IF($A$2="PREMIUM_OI",IFERROR(IF($X$1="ABS",(100*RTD("tos.rtd",,"OPEN_INT","."&F$2&F$1&"C"&$A5)*RTD("tos.rtd",,"LAST","."&F$2&F$1&"C"&$A5)+100*RTD("tos.rtd",,"OPEN_INT","."&F$2&F$1&"P"&$A5)*RTD("tos.rtd",,"LAST","."&F$2&F$1&"P"&$A5))/1000000,(100*RTD("tos.rtd",,"OPEN_INT","."&F$2&F$1&"C"&$A5)*RTD("tos.rtd",,"LAST","."&F$2&F$1&"C"&$A5)-100*RTD("tos.rtd",,"OPEN_INT","."&F$2&F$1&"P"&$A5)*RTD("tos.rtd",,"LAST","."&F$2&F$1&"P"&$A5))/1000000),0),IF($A$2="PREMIUM",IFERROR(IF($X$1="ABS",(100*RTD("tos.rtd",,"VOLUME","."&F$2&F$1&"C"&$A5)*RTD("tos.rtd",,"LAST","."&F$2&F$1&"C"&$A5)+100*RTD("tos.rtd",,"VOLUME","."&F$2&F$1&"P"&$A5)*RTD("tos.rtd",,"LAST","."&F$2&F$1&"P"&$A5))/1000000,(100*RTD("tos.rtd",,"VOLUME","."&F$2&F$1&"C"&$A5)*RTD("tos.rtd",,"LAST","."&F$2&F$1&"C"&$A5)-100*RTD("tos.rtd",,"VOLUME","."&F$2&F$1&"P"&$A5)*RTD("tos.rtd",,"LAST","."&F$2&F$1&"P"&$A5))/1000000),0),IF($A$2="DEX",IFERROR(IF($X$1="ABS",(100*RTD("tos.rtd",,"OPEN_INT","."&F$2&F$1&"C"&$A5)*RTD("tos.rtd",,"DELTA","."&F$2&F$1&"C"&$A5)+100*RTD("tos.rtd",,"OPEN_INT","."&F$2&F$1&"P"&$A5)*RTD("tos.rtd",,"DELTA","."&F$2&F$1&"P"&$A5))/1000,(100*RTD("tos.rtd",,"OPEN_INT","."&F$2&F$1&"C"&$A5)*RTD("tos.rtd",,"DELTA","."&F$2&F$1&"C"&$A5)-100*RTD("tos.rtd",,"OPEN_INT","."&F$2&F$1&"P"&$A5)*RTD("tos.rtd",,"DELTA","."&F$2&F$1&"P"&$A5))/1000),0),IF($A$2="VEX",IFERROR(IF($X$1="ABS",($A$4*$A$4*RTD("tos.rtd",,"VOLUME","."&F$2&F$1&"C"&$A5)*RTD("tos.rtd",,"GAMMA","."&F$2&F$1&"C"&$A5)+$A$4*$A$4*RTD("tos.rtd",,"VOLUME","."&F$2&F$1&"P"&$A5)*RTD("tos.rtd",,"GAMMA","."&F$2&F$1&"P"&$A5))/1000000,($A$4*$A$4*RTD("tos.rtd",,"VOLUME","."&F$2&F$1&"C"&$A5)*RTD("tos.rtd",,"GAMMA","."&F$2&F$1&"C"&$A5)-$A$4*$A$4*RTD("tos.rtd",,"VOLUME","."&F$2&F$1&"P"&$A5)*RTD("tos.rtd",,"GAMMA","."&F$2&F$1&"P"&$A5))/1000000),0),IF($A$2="GEX",IFERROR(IF($X$1="ABS",($A$4*$A$4*RTD("tos.rtd",,"OPEN_INT","."&F$2&F$1&"C"&$A5)*RTD("tos.rtd",,"GAMMA","."&F$2&F$1&"C"&$A5)+$A$4*$A$4*RTD("tos.rtd",,"OPEN_INT","."&F$2&F$1&"P"&$A5)*RTD("tos.rtd",,"GAMMA","."&F$2&F$1&"P"&$A5))/1000000,($A$4*$A$4*RTD("tos.rtd",,"OPEN_INT","."&F$2&F$1&"C"&$A5)*RTD("tos.rtd",,"GAMMA","."&F$2&F$1&"C"&$A5)-$A$4*$A$4*RTD("tos.rtd",,"OPEN_INT","."&F$2&F$1&"P"&$A5)*RTD("tos.rtd",,"GAMMA","."&F$2&F$1&"P"&$A5))/1000000),0),IF($A$2="SKEW",IFERROR(VALUE(IF(RTD("tos.rtd",,"IMPL_VOL","."&F$2&F$1&"P"&$A5)="N/A",0,RTD("tos.rtd",,"IMPL_VOL","."&F$2&F$1&"P"&$A5))),0)-IFERROR(VALUE(IF(RTD("tos.rtd",,"IMPL_VOL","."&F$2&F$1&"C"&$A5)="N/A",0,RTD("tos.rtd",,"IMPL_VOL","."&F$2&F$1&"C"&$A5))),0),IF($A$2="MAXPAIN",IF($A$4>$A5,($A$4-$A5)*IF(RTD("tos.rtd",,"OPEN_INT","."&F$2&F$1&"C"&$A5)="N/A",0,RTD("tos.rtd",,"OPEN_INT","."&F$2&F$1&"C"&$A5)),0)+IF($A$4<$A5,($A$5-$A$4)*IF(RTD("tos.rtd",,"OPEN_INT","."&F$2&F$1&"P"&$A5)="N/A",0,RTD("tos.rtd",,"OPEN_INT","."&F$2&F$1&"P"&$A5)),0),IF($X$1="ABS",IF(RTD("tos.rtd",,$A$2,"."&F$2&F$1&"C"&$A5)="N/A",0,RTD("tos.rtd",,$A$2,"."&F$2&F$1&"C"&$A5))+IF(RTD("tos.rtd",,$A$2,"."&F$2&F$1&"P"&$A5)="N/A",0,RTD("tos.rtd",,$A$2,"."&F$2&F$1&"P"&$A5)),IF(RTD("tos.rtd",,$A$2,"."&F$2&F$1&"C"&$A5)="N/A",0,RTD("tos.rtd",,$A$2,"."&F$2&F$1&"C"&$A5))-IF(RTD("tos.rtd",,$A$2,"."&F$2&F$1&"P"&$A5)="N/A",0,RTD("tos.rtd",,$A$2,"."&F$2&F$1&"P"&$A5)))))))))) -> 0 | G5: =IF($A$2="PREMIUM_OI",IFERROR(IF($X$1="ABS",(100*RTD("tos.rtd",,"OPEN_INT","."&G$2&G$1&"C"&$A5)*RTD("tos.rtd",,"LAST","."&G$2&G$1&"C"&$A5)+100*RTD("tos.rtd",,"OPEN_INT","."&G$2&G$1&"P"&$A5)*RTD("tos.rtd",,"LAST","."&G$2&G$1&"P"&$A5))/1000000,(100*RTD("tos.rtd",,"OPEN_INT","."&G$2&G$1&"C"&$A5)*RTD("tos.rtd",,"LAST","."&G$2&G$1&"C"&$A5)-100*RTD("tos.rtd",,"OPEN_INT","."&G$2&G$1&"P"&$A5)*RTD("tos.rtd",,"LAST","."&G$2&G$1&"P"&$A5))/1000000),0),IF($A$2="PREMIUM",IFERROR(IF($X$1="ABS",(100*RTD("tos.rtd",,"VOLUME","."&G$2&G$1&"C"&$A5)*RTD("tos.rtd",,"LAST","."&G$2&G$1&"C"&$A5)+100*RTD("tos.rtd",,"VOLUME","."&G$2&G$1&"P"&$A5)*RTD("tos.rtd",,"LAST","."&G$2&G$1&"P"&$A5))/1000000,(100*RTD("tos.rtd",,"VOLUME","."&G$2&G$1&"C"&$A5)*RTD("tos.rtd",,"LAST","."&G$2&G$1&"C"&$A5)-100*RTD("tos.rtd",,"VOLUME","."&G$2&G$1&"P"&$A5)*RTD("tos.rtd",,"LAST","."&G$2&G$1&"P"&$A5))/1000000),0),IF($A$2="DEX",IFERROR(IF($X$1="ABS",(100*RTD("tos.rtd",,"OPEN_INT","."&G$2&G$1&"C"&$A5)*RTD("tos.rtd",,"DELTA","."&G$2&G$1&"C"&$A5)+100*RTD("tos.rtd",,"OPEN_INT","."&G$2&G$1&"P"&$A5)*RTD("tos.rtd",,"DELTA","."&G$2&G$1&"P"&$A5))/1000,(100*RTD("tos.rtd",,"OPEN_INT","."&G$2&G$1&"C"&$A5)*RTD("tos.rtd",,"DELTA","."&G$2&G$1&"C"&$A5)-100*RTD("tos.rtd",,"OPEN_INT","."&G$2&G$1&"P"&$A5)*RTD("tos.rtd",,"DELTA","."&G$2&G$1&"P"&$A5))/1000),0),IF($A$2="VEX",IFERROR(IF($X$1="ABS",($A$4*$A$4*RTD("tos.rtd",,"VOLUME","."&G$2&G$1&"C"&$A5)*RTD("tos.rtd",,"GAMMA","."&G$2&G$1&"C"&$A5)+$A$4*$A$4*RTD("tos.rtd",,"VOLUME","."&G$2&G$1&"P"&$A5)*RTD("tos.rtd",,"GAMMA","."&G$2&G$1&"P"&$A5))/1000000,($A$4*$A$4*RTD("tos.rtd",,"VOLUME","."&G$2&G$1&"C"&$A5)*RTD("tos.rtd",,"GAMMA","."&G$2&G$1&"C"&$A5)-$A$4*$A$4*RTD("tos.rtd",,"VOLUME","."&G$2&G$1&"P"&$A5)*RTD("tos.rtd",,"GAMMA","."&G$2&G$1&"P"&$A5))/1000000),0),IF($A$2="GEX",IFERROR(IF($X$1="ABS",($A$4*$A$4*RTD("tos.rtd",,"OPEN_INT","."&G$2&G$1&"C"&$A5)*RTD("tos.rtd",,"GAMMA","."&G$2&G$1&"C"&$A5)+$A$4*$A$4*RTD("tos.rtd",,"OPEN_INT","."&G$2&G$1&"P"&$A5)*RTD("tos.rtd",,"GAMMA","."&G$2&G$1&"P"&$A5))/1000000,($A$4*$A$4*RTD("tos.rtd",,"OPEN_INT","."&G$2&G$1&"C"&$A5)*RTD("tos.rtd",,"GAMMA","."&G$2&G$1&"C"&$A5)-$A$4*$A$4*RTD("tos.rtd",,"OPEN_INT","."&G$2&G$1&"P"&$A5)*RTD("tos.rtd",,"GAMMA","."&G$2&G$1&"P"&$A5))/1000000),0),IF($A$2="SKEW",IFERROR(VALUE(IF(RTD("tos.rtd",,"IMPL_VOL","."&G$2&G$1&"P"&$A5)="N/A",0,RTD("tos.rtd",,"IMPL_VOL","."&G$2&G$1&"P"&$A5))),0)-IFERROR(VALUE(IF(RTD("tos.rtd",,"IMPL_VOL","."&G$2&G$1&"C"&$A5)="N/A",0,RTD("tos.rtd",,"IMPL_VOL","."&G$2&G$1&"C"&$A5))),0),IF($A$2="MAXPAIN",IF($A$4>$A5,($A$4-$A5)*IF(RTD("tos.rtd",,"OPEN_INT","."&G$2&G$1&"C"&$A5)="N/A",0,RTD("tos.rtd",,"OPEN_INT","."&G$2&G$1&"C"&$A5)),0)+IF($A$4<$A5,($A$5-$A$4)*IF(RTD("tos.rtd",,"OPEN_INT","."&G$2&G$1&"P"&$A5)="N/A",0,RTD("tos.rtd",,"OPEN_INT","."&G$2&G$1&"P"&$A5)),0),IF($X$1="ABS",IF(RTD("tos.rtd",,$A$2,"."&G$2&G$1&"C"&$A5)="N/A",0,RTD("tos.rtd",,$A$2,"."&G$2&G$1&"C"&$A5))+IF(RTD("tos.rtd",,$A$2,"."&G$2&G$1&"P"&$A5)="N/A",0,RTD("tos.rtd",,$A$2,"."&G$2&G$1&"P"&$A5)),IF(RTD("tos.rtd",,$A$2,"."&G$2&G$1&"C"&$A5)="N/A",0,RTD("tos.rtd",,$A$2,"."&G$2&G$1&"C"&$A5))-IF(RTD("tos.rtd",,$A$2,"."&G$2&G$1&"P"&$A5)="N/A",0,RTD("tos.rtd",,$A$2,"."&G$2&G$1&"P"&$A5)))))))))) -> 0 | H5: =IF($A$2="PREMIUM_OI",IFERROR(IF($X$1="ABS",(100*RTD("tos.rtd",,"OPEN_INT","."&H$2&H$1&"C"&$A5)*RTD("tos.rtd",,"LAST","."&H$2&H$1&"C"&$A5)+100*RTD("tos.rtd",,"OPEN_INT","."&H$2&H$1&"P"&$A5)*RTD("tos.rtd",,"LAST","."&H$2&H$1&"P"&$A5))/1000000,(100*RTD("tos.rtd",,"OPEN_INT","."&H$2&H$1&"C"&$A5)*RTD("tos.rtd",,"LAST","."&H$2&H$1&"C"&$A5)-100*RTD("tos.rtd",,"OPEN_INT","."&H$2&H$1&"P"&$A5)*RTD("tos.rtd",,"LAST","."&H$2&H$1&"P"&$A5))/1000000),0),IF($A$2="PREMIUM",IFERROR(IF($X$1="ABS",(100*RTD("tos.rtd",,"VOLUME","."&H$2&H$1&"C"&$A5)*RTD("tos.rtd",,"LAST","."&H$2&H$1&"C"&$A5)+100*RTD("tos.rtd",,"VOLUME","."&H$2&H$1&"P"&$A5)*RTD("tos.rtd",,"LAST","."&H$2&H$1&"P"&$A5))/1000000,(100*RTD("tos.rtd",,"VOLUME","."&H$2&H$1&"C"&$A5)*RTD("tos.rtd",,"LAST","."&H$2&H$1&"C"&$A5)-100*RTD("tos.rtd",,"VOLUME","."&H$2&H$1&"P"&$A5)*RTD("tos.rtd",,"LAST","."&H$2&H$1&"P"&$A5))/1000000),0),IF($A$2="DEX",IFERROR(IF($X$1="ABS",(100*RTD("tos.rtd",,"OPEN_INT","."&H$2&H$1&"C"&$A5)*RTD("tos.rtd",,"DELTA","."&H$2&H$1&"C"&$A5)+100*RTD("tos.rtd",,"OPEN_INT","."&H$2&H$1&"P"&$A5)*RTD("tos.rtd",,"DELTA","."&H$2&H$1&"P"&$A5))/1000,(100*RTD("tos.rtd",,"OPEN_INT","."&H$2&H$1&"C"&$A5)*RTD("tos.rtd",,"DELTA","."&H$2&H$1&"C"&$A5)-100*RTD("tos.rtd",,"OPEN_INT","."&H$2&H$1&"P"&$A5)*RTD("tos.rtd",,"DELTA","."&H$2&H$1&"P"&$A5))/1000),0),IF($A$2="VEX",IFERROR(IF($X$1="ABS",($A$4*$A$4*RTD("tos.rtd",,"VOLUME","."&H$2&H$1&"C"&$A5)*RTD("tos.rtd",,"GAMMA","."&H$2&H$1&"C"&$A5)+$A$4*$A$4*RTD("tos.rtd",,"VOLUME","."&H$2&H$1&"P"&$A5)*RTD("tos.rtd",,"GAMMA","."&H$2&H$1&"P"&$A5))/1000000,($A$4*$A$4*RTD("tos.rtd",,"VOLUME","."&H$2&H$1&"C"&$A5)*RTD("tos.rtd",,"GAMMA","."&H$2&H$1&"C"&$A5)-$A$4*$A$4*RTD("tos.rtd",,"VOLUME","."&H$2&H$1&"P"&$A5)*RTD("tos.rtd",,"GAMMA","."&H$2&H$1&"P"&$A5))/1000000),0),IF($A$2="GEX",IFERROR(IF($X$1="ABS",($A$4*$A$4*RTD("tos.rtd",,"OPEN_INT","."&H$2&H$1&"C"&$A5)*RTD("tos.rtd",,"GAMMA","."&H$2&H$1&"C"&$A5)+$A$4*$A$4*RTD("tos.rtd",,"OPEN_INT","."&H$2&H$1&"P"&$A5)*RTD("tos.rtd",,"GAMMA","."&H$2&H$1&"P"&$A5))/1000000,($A$4*$A$4*RTD("tos.rtd",,"OPEN_INT","."&H$2&H$1&"C"&$A5)*RTD("tos.rtd",,"GAMMA","."&H$2&H$1&"C"&$A5)-$A$4*$A$4*RTD("tos.rtd",,"OPEN_INT","."&H$2&H$1&"P"&$A5)*RTD("tos.rtd",,"GAMMA","."&H$2&H$1&"P"&$A5))/1000000),0),IF($A$2="SKEW",IFERROR(VALUE(IF(RTD("tos.rtd",,"IMPL_VOL","."&H$2&H$1&"P"&$A5)="N/A",0,RTD("tos.rtd",,"IMPL_VOL","."&H$2&H$1&"P"&$A5))),0)-IFERROR(VALUE(IF(RTD("tos.rtd",,"IMPL_VOL","."&H$2&H$1&"C"&$A5)="N/A",0,RTD("tos.rtd",,"IMPL_VOL","."&H$2&H$1&"C"&$A5))),0),IF($A$2="MAXPAIN",IF($A$4>$A5,($A$4-$A5)*IF(RTD("tos.rtd",,"OPEN_INT","."&H$2&H$1&"C"&$A5)="N/A",0,RTD("tos.rtd",,"OPEN_INT","."&H$2&H$1&"C"&$A5)),0)+IF($A$4<$A5,($A$5-$A$4)*IF(RTD("tos.rtd",,"OPEN_INT","."&H$2&H$1&"P"&$A5)="N/A",0,RTD("tos.rtd",,"OPEN_INT","."&H$2&H$1&"P"&$A5)),0),IF($X$1="ABS",IF(RTD("tos.rtd",,$A$2,"."&H$2&H$1&"C"&$A5)="N/A",0,RTD("tos.rtd",,$A$2,"."&H$2&H$1&"C"&$A5))+IF(RTD("tos.rtd",,$A$2,"."&H$2&H$1&"P"&$A5)="N/A",0,RTD("tos.rtd",,$A$2,"."&H$2&H$1&"P"&$A5)),IF(RTD("tos.rtd",,$A$2,"."&H$2&H$1&"C"&$A5)="N/A",0,RTD("tos.rtd",,$A$2,"."&H$2&H$1&"C"&$A5))-IF(RTD("tos.rtd",,$A$2,"."&H$2&H$1&"P"&$A5)="N/A",0,RTD("tos.rtd",,$A$2,"."&H$2&H$1&"P"&$A5)))))))))) -> 0 | I5: =IF($A$2="PREMIUM_OI",IFERROR(IF($X$1="ABS",(100*RTD("tos.rtd",,"OPEN_INT","."&I$2&I$1&"C"&$A5)*RTD("tos.rtd",,"LAST","."&I$2&I$1&"C"&$A5)+100*RTD("tos.rtd",,"OPEN_INT","."&I$2&I$1&"P"&$A5)*RTD("tos.rtd",,"LAST","."&I$2&I$1&"P"&$A5))/1000000,(100*RTD("tos.rtd",,"OPEN_INT","."&I$2&I$1&"C"&$A5)*RTD("tos.rtd",,"LAST","."&I$2&I$1&"C"&$A5)-100*RTD("tos.rtd",,"OPEN_INT","."&I$2&I$1&"P"&$A5)*RTD("tos.rtd",,"LAST","."&I$2&I$1&"P"&$A5))/1000000),0),IF($A$2="PREMIUM",IFERROR(IF($X$1="ABS",(100*RTD("tos.rtd",,"VOLUME","."&I$2&I$1&"C"&$A5)*RTD("tos.rtd",,"LAST","."&I$2&I$1&"C"&$A5)+100*RTD("tos.rtd",,"VOLUME","."&I$2&I$1&"P"&$A5)*RTD("tos.rtd",,"LAST","."&I$2&I$1&"P"&$A5))/1000000,(100*RTD("tos.rtd",,"VOLUME","."&I$2&I$1&"C"&$A5)*RTD("tos.rtd",,"LAST","."&I$2&I$1&"C"&$A5)-100*RTD("tos.rtd",,"VOLUME","."&I$2&I$1&"P"&$A5)*RTD("tos.rtd",,"LAST","."&I$2&I$1&"P"&$A5))/1000000),0),IF($A$2="DEX",IFERROR(IF($X$1="ABS",(100*RTD("tos.rtd",,"OPEN_INT","."&I$2&I$1&"C"&$A5)*RTD("tos.rtd",,"DELTA","."&I$2&I$1&"C"&$A5)+100*RTD("tos.rtd",,"OPEN_INT","."&I$2&I$1&"P"&$A5)*RTD("tos.rtd",,"DELTA","."&I$2&I$1&"P"&$A5))/1000,(100*RTD("tos.rtd",,"OPEN_INT","."&I$2&I$1&"C"&$A5)*RTD("tos.rtd",,"DELTA","."&I$2&I$1&"C"&$A5)-100*RTD("tos.rtd",,"OPEN_INT","."&I$2&I$1&"P"&$A5)*RTD("tos.rtd",,"DELTA","."&I$2&I$1&"P"&$A5))/1000),0),IF($A$2="VEX",IFERROR(IF($X$1="ABS",($A$4*$A$4*RTD("tos.rtd",,"VOLUME","."&I$2&I$1&"C"&$A5)*RTD("tos.rtd",,"GAMMA","."&I$2&I$1&"C"&$A5)+$A$4*$A$4*RTD("tos.rtd",,"VOLUME","."&I$2&I$1&"P"&$A5)*RTD("tos.rtd",,"GAMMA","."&I$2&I$1&"P"&$A5))/1000000,($A$4*$A$4*RTD("tos.rtd",,"VOLUME","."&I$2&I$1&"C"&$A5)*RTD("tos.rtd",,"GAMMA","."&I$2&I$1&"C"&$A5)-$A$4*$A$4*RTD("tos.rtd",,"VOLUME","."&I$2&I$1&"P"&$A5)*RTD("tos.rtd",,"GAMMA","."&I$2&I$1&"P"&$A5))/1000000),0),IF($A$2="GEX",IFERROR(IF($X$1="ABS",($A$4*$A$4*RTD("tos.rtd",,"OPEN_INT","."&I$2&I$1&"C"&$A5)*RTD("tos.rtd",,"GAMMA","."&I$2&I$1&"C"&$A5)+$A$4*$A$4*RTD("tos.rtd",,"OPEN_INT","."&I$2&I$1&"P"&$A5)*RTD("tos.rtd",,"GAMMA","."&I$2&I$1&"P"&$A5))/1000000,($A$4*$A$4*RTD("tos.rtd",,"OPEN_INT","."&I$2&I$1&"C"&$A5)*RTD("tos.rtd",,"GAMMA","."&I$2&I$1&"C"&$A5)-$A$4*$A$4*RTD("tos.rtd",,"OPEN_INT","."&I$2&I$1&"P"&$A5)*RTD("tos.rtd",,"GAMMA","."&I$2&I$1&"P"&$A5))/1000000),0),IF($A$2="SKEW",IFERROR(VALUE(IF(RTD("tos.rtd",,"IMPL_VOL","."&I$2&I$1&"P"&$A5)="N/A",0,RTD("tos.rtd",,"IMPL_VOL","."&I$2&I$1&"P"&$A5))),0)-IFERROR(VALUE(IF(RTD("tos.rtd",,"IMPL_VOL","."&I$2&I$1&"C"&$A5)="N/A",0,RTD("tos.rtd",,"IMPL_VOL","."&I$2&I$1&"C"&$A5))),0),IF($A$2="MAXPAIN",IF($A$4>$A5,($A$4-$A5)*IF(RTD("tos.rtd",,"OPEN_INT","."&I$2&I$1&"C"&$A5)="N/A",0,RTD("tos.rtd",,"OPEN_INT","."&I$2&I$1&"C"&$A5)),0)+IF($A$4<$A5,($A$5-$A$4)*IF(RTD("tos.rtd",,"OPEN_INT","."&I$2&I$1&"P"&$A5)="N/A",0,RTD("tos.rtd",,"OPEN_INT","."&I$2&I$1&"P"&$A5)),0),IF($X$1="ABS",IF(RTD("tos.rtd",,$A$2,"."&I$2&I$1&"C"&$A5)="N/A",0,RTD("tos.rtd",,$A$2,"."&I$2&I$1&"C"&$A5))+IF(RTD("tos.rtd",,$A$2,"."&I$2&I$1&"P"&$A5)="N/A",0,RTD("tos.rtd",,$A$2,"."&I$2&I$1&"P"&$A5)),IF(RTD("tos.rtd",,$A$2,"."&I$2&I$1&"C"&$A5)="N/A",0,RTD("tos.rtd",,$A$2,"."&I$2&I$1&"C"&$A5))-IF(RTD("tos.rtd",,$A$2,"."&I$2&I$1&"P"&$A5)="N/A",0,RTD("tos.rtd",,$A$2,"."&I$2&I$1&"P"&$A5)))))))))) -> 0 | ... W5: =IF($A$2="PREMIUM_OI",IFERROR(IF($X$1="ABS",(100*RTD("tos.rtd",,"OPEN_INT","."&W$2&W$1&"C"&$A5)*RTD("tos.rtd",,"LAST","."&W$2&W$1&"C"&$A5)+100*RTD("tos.rtd",,"OPEN_INT","."&W$2&W$1&"P"&$A5)*RTD("tos.rtd",,"LAST","."&W$2&W$1&"P"&$A5))/1000000,(100*RTD("tos.rtd",,"OPEN_INT","."&W$2&W$1&"C"&$A5)*RTD("tos.rtd",,"LAST","."&W$2&W$1&"C"&$A5)-100*RTD("tos.rtd",,"OPEN_INT","."&W$2&W$1&"P"&$A5)*RTD("tos.rtd",,"LAST","."&W$2&W$1&"P"&$A5))/1000000),0),IF($A$2="PREMIUM",IFERROR(IF($X$1="ABS",(100*RTD("tos.rtd",,"VOLUME","."&W$2&W$1&"C"&$A5)*RTD("tos.rtd",,"LAST","."&W$2&W$1&"C"&$A5)+100*RTD("tos.rtd",,"VOLUME","."&W$2&W$1&"P"&$A5)*RTD("tos.rtd",,"LAST","."&W$2&W$1&"P"&$A5))/1000000,(100*RTD("tos.rtd",,"VOLUME","."&W$2&W$1&"C"&$A5)*RTD("tos.rtd",,"LAST","."&W$2&W$1&"C"&$A5)-100*RTD("tos.rtd",,"VOLUME","."&W$2&W$1&"P"&$A5)*RTD("tos.rtd",,"LAST","."&W$2&W$1&"P"&$A5))/1000000),0),IF($A$2="DEX",IFERROR(IF($X$1="ABS",(100*RTD("tos.rtd",,"OPEN_INT","."&W$2&W$1&"C"&$A5)*RTD("tos.rtd",,"DELTA","."&W$2&W$1&"C"&$A5)+100*RTD("tos.rtd",,"OPEN_INT","."&W$2&W$1&"P"&$A5)*RTD("tos.rtd",,"DELTA","."&W$2&W$1&"P"&$A5))/1000,(100*RTD("tos.rtd",,"OPEN_INT","."&W$2&W$1&"C"&$A5)*RTD("tos.rtd",,"DELTA","."&W$2&W$1&"C"&$A5)-100*RTD("tos.rtd",,"OPEN_INT","."&W$2&W$1&"P"&$A5)*RTD("tos.rtd",,"DELTA","."&W$2&W$1&"P"&$A5))/1000),0),IF($A$2="VEX",IFERROR(IF($X$1="ABS",($A$4*$A$4*RTD("tos.rtd",,"VOLUME","."&W$2&W$1&"C"&$A5)*RTD("tos.rtd",,"GAMMA","."&W$2&W$1&"C"&$A5)+$A$4*$A$4*RTD("tos.rtd",,"VOLUME","."&W$2&W$1&"P"&$A5)*RTD("tos.rtd",,"GAMMA","."&W$2&W$1&"P"&$A5))/1000000,($A$4*$A$4*RTD("tos.rtd",,"VOLUME","."&W$2&W$1&"C"&$A5)*RTD("tos.rtd",,"GAMMA","."&W$2&W$1&"C"&$A5)-$A$4*$A$4*RTD("tos.rtd",,"VOLUME","."&W$2&W$1&"P"&$A5)*RTD("tos.rtd",,"GAMMA","."&W$2&W$1&"P"&$A5))/1000000),0),IF($A$2="GEX",IFERROR(IF($X$1="ABS",($A$4*$A$4*RTD("tos.rtd",,"OPEN_INT","."&W$2&W$1&"C"&$A5)*RTD("tos.rtd",,"GAMMA","."&W$2&W$1&"C"&$A5)+$A$4*$A$4*RTD("tos.rtd",,"OPEN_INT","."&W$2&W$1&"P"&$A5)*RTD("tos.rtd",,"GAMMA","."&W$2&W$1&"P"&$A5))/1000000,($A$4*$A$4*RTD("tos.rtd",,"OPEN_INT","."&W$2&W$1&"C"&$A5)*RTD("tos.rtd",,"GAMMA","."&W$2&W$1&"C"&$A5)-$A$4*$A$4*RTD("tos.rtd",,"OPEN_INT","."&W$2&W$1&"P"&$A5)*RTD("tos.rtd",,"GAMMA","."&W$2&W$1&"P"&$A5))/1000000),0),IF($A$2="SKEW",IFERROR(VALUE(IF(RTD("tos.rtd",,"IMPL_VOL","."&W$2&W$1&"P"&$A5)="N/A",0,RTD("tos.rtd",,"IMPL_VOL","."&W$2&W$1&"P"&$A5))),0)-IFERROR(VALUE(IF(RTD("tos.rtd",,"IMPL_VOL","."&W$2&W$1&"C"&$A5)="N/A",0,RTD("tos.rtd",,"IMPL_VOL","."&W$2&W$1&"C"&$A5))),0),IF($A$2="MAXPAIN",IF($A$4>$A5,($A$4-$A5)*IF(RTD("tos.rtd",,"OPEN_INT","."&W$2&W$1&"C"&$A5)="N/A",0,RTD("tos.rtd",,"OPEN_INT","."&W$2&W$1&"C"&$A5)),0)+IF($A$4<$A5,($A$5-$A$4)*IF(RTD("tos.rtd",,"OPEN_INT","."&W$2&W$1&"P"&$A5)="N/A",0,RTD("tos.rtd",,"OPEN_INT","."&W$2&W$1&"P"&$A5)),0),IF($X$1="ABS",IF(RTD("tos.rtd",,$A$2,"."&W$2&W$1&"C"&$A5)="N/A",0,RTD("tos.rtd",,$A$2,"."&W$2&W$1&"C"&$A5))+IF(RTD("tos.rtd",,$A$2,"."&W$2&W$1&"P"&$A5)="N/A",0,RTD("tos.rtd",,$A$2,"."&W$2&W$1&"P"&$A5)),IF(RTD("tos.rtd",,$A$2,"."&W$2&W$1&"C"&$A5)="N/A",0,RTD("tos.rtd",,$A$2,"."&W$2&W$1&"C"&$A5))-IF(RTD("tos.rtd",,$A$2,"."&W$2&W$1&"P"&$A5)="N/A",0,RTD("tos.rtd",,$A$2,"."&W$2&W$1&"P"&$A5)))))))))) -> 0 | X5: =SUMPRODUCT(B5:W5,$B$52:$W$52) -> 0 | Y5: =+X5 -> 0 | Z5: =+'OI-VOL'!Y5 -> 0 | AA5: =IF(AND(A5>$Y$52,A5<$Y$4),ABS(AVERAGE(Y4:Y6))) -> FALSE | AB5: =SUM(AC5:BW5) -> 260892200 | AC5: =MAX(0, $A5-AC$4)*IF(RTD("tos.rtd",,"OPEN_INT","."&$AB$3&$AB$4&"C"&AC$4)="N/A",0,RTD("tos.rtd",,"OPEN_INT","."&$AB$3&$AB$4&"C"&AC$4))*100 + MAX(0, AC$4-$A5)*IF(RTD("tos.rtd",,"OPEN_INT","."&$AB$3&$AB$4&"P"&AC$4)="N/A",0,RTD("tos.rtd",,"OPEN_INT","."&$AB$3&$AB$4&"P"&AC$4))*100 -> 0 | AD5: =MAX(0, $A5-AD$4)*IF(RTD("tos.rtd",,"OPEN_INT","."&$AB$3&$AB$4&"C"&AD$4)="N/A",0,RTD("tos.rtd",,"OPEN_INT","."&$AB$3&$AB$4&"C"&AD$4))*100 + MAX(0, AD$4-$A5)*IF(RTD("tos.rtd",,"OPEN_INT","."&$AB$3&$AB$4&"P"&AD$4)="N/A",0,RTD("tos.rtd",,"OPEN_INT","."&$AB$3&$AB$4&"P"&AD$4))*100 -> 0 | AE5: =MAX(0, $A5-AE$4)*IF(RTD("tos.rtd",,"OPEN_INT","."&$AB$3&$AB$4&"C"&AE$4)="N/A",0,RTD("tos.rtd",,"OPEN_INT","."&$AB$3&$AB$4&"C"&AE$4))*100 + MAX(0, AE$4-$A5)*IF(RTD("tos.rtd",,"OPEN_INT","."&$AB$3&$AB$4&"P"&AE$4)="N/A",0,RTD("tos.rtd",,"OPEN_INT","."&$AB$3&$AB$4&"P"&AE$4))*100 -> 0 | AF5: =MAX(0, $A5-AF$4)*IF(RTD("tos.rtd",,"OPEN_INT","."&$AB$3&$AB$4&"C"&AF$4)="N/A",0,RTD("tos.rtd",,"OPEN_INT","."&$AB$3&$AB$4&"C"&AF$4))*100 + MAX(0, AF$4-$A5)*IF(RTD("tos.rtd",,"OPEN_INT","."&$AB$3&$AB$4&"P"&AF$4)="N/A",0,RTD("tos.rtd",,"OPEN_INT","."&$AB$3&$AB$4&"P"&AF$4))*100 -> 0 | AG5: =MAX(0, $A5-AG$4)*IF(RTD("tos.rtd",,"OPEN_INT","."&$AB$3&$AB$4&"C"&AG$4)="N/A",0,RTD("tos.rtd",,"OPEN_INT","."&$AB$3&$AB$4&"C"&AG$4))*100 + MAX(0, AG$4-$A5)*IF(RTD("tos.rtd",,"OPEN_INT","."&$AB$3&$AB$4&"P"&AG$4)="N/A",0,RTD("tos.rtd",,"OPEN_INT","."&$AB$3&$AB$4&"P"&AG$4))*100 -> 0 | AH5: =MAX(0, $A5-AH$4)*IF(RTD("tos.rtd",,"OPEN_INT","."&$AB$3&$AB$4&"C"&AH$4)="N/A",0,RTD("tos.rtd",,"OPEN_INT","."&$AB$3&$AB$4&"C"&AH$4))*100 + MAX(0, AH$4-$A5)*IF(RTD("tos.rtd",,"OPEN_INT","."&$AB$3&$AB$4&"P"&AH$4)="N/A",0,RTD("tos.rtd",,"OPEN_INT","."&$AB$3&$AB$4&"P"&AH$4))*100 -> 0 | AI5: =MAX(0, $A5-AI$4)*IF(RTD("tos.rtd",,"OPEN_INT","."&$AB$3&$AB$4&"C"&AI$4)="N/A",0,RTD("tos.rtd",,"OPEN_INT","."&$AB$3&$AB$4&"C"&AI$4))*100 + MAX(0, AI$4-$A5)*IF(RTD("tos.rtd",,"OPEN_INT","."&$AB$3&$AB$4&"P"&AI$4)="N/A",0,RTD("tos.rtd",,"OPEN_INT","."&$AB$3&$AB$4&"P"&AI$4))*100 -> 0 | AJ5: =MAX(0, $A5-AJ$4)*IF(RTD("tos.rtd",,"OPEN_INT","."&$AB$3&$AB$4&"C"&AJ$4)="N/A",0,RTD("tos.rtd",,"OPEN_INT","."&$AB$3&$AB$4&"C"&AJ$4))*100 + MAX(0, AJ$4-$A5)*IF(RTD("tos.rtd",,"OPEN_INT","."&$AB$3&$AB$4&"P"&AJ$4)="N/A",0,RTD("tos.rtd",,"OPEN_INT","."&$AB$3&$AB$4&"P"&AJ$4))*100 -> 950600 | ... BW5: =MAX(0, $A5-BW$4)*IF(RTD("tos.rtd",,"OPEN_INT","."&$AB$3&$AB$4&"C"&BW$4)="N/A",0,RTD("tos.rtd",,"OPEN_INT","."&$AB$3&$AB$4&"C"&BW$4))*100 + MAX(0, BW$4-$A5)*IF(RTD("tos.rtd",,"OPEN_INT","."&$AB$3&$AB$4&"P"&BW$4)="N/A",0,RTD("tos.rtd",,"OPEN_INT","."&$AB$3&$AB$4&"P"&BW$4))*100 -> 0
